Workbook

Sheet 計畫總表
A1: 編號 | B1: 來源回答 | C1: 類別 | D1: 主辦部會 | E1: 執行/主管單位 | F1: 計畫或資源名稱 | G1: 115年中小企業競爭力方案 | H1: 內容重點 | I1: 補助上限(萬元) | J1: 上限定義 | K1: 補助型態 | L1: 申請對象 | M1: 企業可直接申請? | N1: 申請截止日 | O1: 期限說明 | P1: 無截止日時的狀態 | Q1: 申請狀態 | R1: 距截止天數 | S1: 查證結果 | T1: 核對說明與更正 | U1: 資料來源
A2: 1 | B2: 第一則(經濟部) | C2: 研發補助與投資 | D2: 經濟部 | E2: 產業技術司 | F2: A+企業創新研發淬鍊計畫-AI應用躍昇計畫 | G2: =IF(COUNTIF(比對結果!$G$2:$G$80,A2)>0,"✓","") | H2: 鼓勵企業結合SI業者或法人開發AI應用並於場域驗證;法人科專已開發31個共通應用模型、導入279家廠商 | I2: 3000 | J2: 每案:導入型2,000+SI加碼1,000;擴散型2,000;補助不超過總經費50% | K2: 現金補助 | L2: 企業、SI業者、法人 | M2: 是 | N2: 45989 | O2: 114年度受理至2025-11-28(媒體報導);115年度是否另有徵案未查到 | Q2: =IF(ISNUMBER(N2),IF(N2<統計!$B$2,"已截止","受理中"),P2) -> 已截止 | R2: =IF(ISNUMBER(N2),N2-統計!$B$2,"") -> -326 | S2: 部分核對 | T2: 官方新聞確認上限與31個模型、279家;總經費5億元與受理期限來自媒體;官方頁未載期限。115年度徵案未查到,請至A+計畫網站確認 | U2: https://www.moea.gov.tw/MNS/populace/news/News.aspx?kind=1&menu_id=40&news_id=120600
A3: 2 | B3: 第一則(經濟部) | C3: 研發補助與投資 | D3: 經濟部 | E3: 產業技術司 | F3: A+企業創新研發淬鍊計畫-國際創新研發合作補助(AI加碼20%) | G3: =IF(COUNTIF(比對結果!$G$2:$G$80,A3)>0,"✓","") | H3: AI技術研發合作及參與國際標準制定,核定補助款可加碼最多20%,加碼後不超過核定計畫總經費50% | J3: 加碼上限20%(非獨立補助額度) | K3: 現金補助加碼 | L3: 企業 | M3: 是 | O3: 全案實施至2028-12-29(報導) | P3: 未確認 | Q3: =IF(ISNUMBER(N3),IF(N3<統計!$B$2,"已截止","受理中"),P3) -> 未確認 | R3: =IF(ISNUMBER(N3),N3-統計!$B$2,"") | S3: 僅媒體或二手 | T3: 僅聯合報報導,A+官方頁未能找到AI加碼說明,無法核對 | U3: https://udn.com/news/story/7240/9244366
A4: 3 | B4: 第一則(經濟部) | C4: 研發補助與投資 | D4: 經濟部 | E4: 產業技術司 | F4: IC設計攻頂補助計畫 | G4: =IF(COUNTIF(比對結果!$G$2:$G$80,A4)>0,"✓","") | H4: 115年度聚焦衛星通訊、機器人、無人機等晶片與系統開發,並鼓勵運用AI整合軟硬體開發百工百業應用系統 | J4: 官方頁未載金額 | K4: 現金補助 | L4: IC設計業者 | M4: 限特定對象 | N4: 46112 | O4: 115年度受理至2026-03-31 17:00(官方頁) | Q4: =IF(ISNUMBER(N4),IF(N4<統計!$B$2,"已截止","受理中"),P4) -> 已截止 | R4: =IF(ISNUMBER(N4),N4-統計!$B$2,"") -> -203 | S4: 部分核對 | T4: 官方頁核對期限與重點領域;補助金額與比例未載 | U4: https://service.moea.gov.tw/EE514/tw/aiip/336.html
A5: 4 | B5: 第一則(經濟部) | C5: 研發補助與投資 | D5: 經濟部 | E5: 產業技術司 | F5: 無人機關鍵晶片及模組自主開發研發補助計畫 | G5: =IF(COUNTIF(比對結果!$G$2:$G$80,A5)>0,"✓","") | H5: 協助廠商開發無人機AI影像晶片模組與低成本飛行控制板 | J5: 未查到 | K5: 現金補助 | L5: 晶片廠、系統廠 | M5: 限特定對象 | O5: 未查到 | P5: 未確認 | Q5: =IF(ISNUMBER(N5),IF(N5<統計!$B$2,"已截止","受理中"),P5) -> 未確認 | R5: =IF(ISNUMBER(N5),N5-統計!$B$2,"") | S5: 僅媒體或二手 | T5: 僅業界科專頁面的計畫描述(頁面為舊資料);115年度是否徵案、金額與期限未能確認 | U5: https://www.moea.gov.tw/MNS/doit/content/Content.aspx?menu_id=13392
A6: 5 | B6: 第一則(經濟部) | C6: 研發補助與投資 | D6: 經濟部 | E6: 產業發展署 | F6: 主題式-製造業AI升級擴散與機器人關鍵感知模組整合研發計畫 | G6: =IF(COUNTIF(比對結果!$G$2:$G$80,A6)>0,"✓","") | H6: 產業升級創新平台主題式研發計畫,配合AI新十大建設 | J6: 公告以圖卡呈現,文字未載 | K6: 現金補助 | L6: 未確認 | M6: 未確認 | N6: 46203 | O6: 公告日2026-05-29,受理至2026-06-30 | Q6: =IF(ISNUMBER(N6),IF(N6<統計!$B$2,"已截止","受理中"),P6) -> 已截止 | R6: =IF(ISNUMBER(N6),N6-統計!$B$2,"") -> -112 | S6: 部分核對 | T6: 產業署新聞確認公告日與截止日;補助上限、對象未能讀取(產業升級創新平台網頁禁止擷取) | U6: https://www.ida.gov.tw/ctlr?PRO=news.rwdNewsView&id=43221
A7: 6 | B7: 第一則(經濟部) | C7: 研發補助與投資 | D7: 經濟部 | E7: 產業發展署(中國生產力中心執行) | F7: 智慧機械-產業聚落供應鏈數位串流暨AI應用 | G7: =IF(COUNTIF(比對結果!$G$2:$G$80,A7)>0,"✓","") -> ✓ | H7: 中小型製造業結合上下游供應鏈,以資訊系統串聯並導入AI加值應用;須委外SI業者 | I7: 1500 | J7: 每案;不超過總經費50%;卓越或潛力中堅企業、新創各可加碼10% | K7: 現金補助 | L7: 中小型製造業(須工廠登記) | M7: 限特定對象 | N7: 46146 | O7: 收件至2026-05-04 17:30;執行期不晚於2027-10-31 | Q7: =IF(ISNUMBER(N7),IF(N7<統計!$B$2,"已截止","受理中"),P7) -> 已截止 | R7: =IF(ISNUMBER(N7),N7-統計!$B$2,"") -> -169 | S7: 已核對(官方) | T7: 更正:先前回答的500萬元為114年版「先期顧問規劃案」上限;115年3月版申請須知上限為1,500萬元。與你提供的115年方案彙整表一致(1,500萬、50%、5/4 17:30、執行至116/10/31) | U7: https://keid.nat.gov.tw/cloud/Web/UpWebload/ACE60748-3BEA-43F0-B094-9783B1E3039B.pdf
A8: 7 | B8: 第一則(經濟部) | C8: 導入輔導與補助 | D8: 經濟部 | E8: 產業發展署 | F8: 產業競爭力輔導團(AI升級三階段) | G8: =IF(COUNTIF(比對結果!$G$2:$G$80,A8)>0,"✓","") | H8: 特別預算460億元;階段一AI診斷、階段二AI工具導入與人才培訓、階段三研發轉型;截至2026-07已輔導9,249家企業(93%為中小企業) | I8: 500 | J8: 研發轉型個案最高500萬(產業聯盟最高4,000萬);診斷約19萬、AI工具最高10萬、人才培訓最高12萬 | K8: 輔導+補助 | L8: 製造業等企業(須先申請並通過資格審核) | M8: 是 | O8: 官方平台持續受理,未見截止日 | P8: 常態開放 | Q8: =IF(ISNUMBER(N8),IF(N8<統計!$B$2,"已截止","受理中"),P8) -> 常態開放 | R8: =IF(ISNUMBER(N8),N8-統計!$B$2,"") | S8: 部分核對 | T8: 9,249家、93%、397項AI工具經中央社報導核對;工具最高10萬、研發500萬/4,000萬與官方PDF相符。診斷補助有衝突:多數報導為19萬+自付1萬,官方PDF摘要顯示18萬+自付2萬,請以申請須知為準 | U8: https://eii.nat.gov.tw/moeai-plus/uploads/downloads/01KXHVG2BBBWKXBZ991F4NEFQD.pdf
A9: 8 | B9: 第一則(經濟部) | C9: 工具、算力或平台 | D9: 經濟部 | E9: 產業發展署 | F9: 產業競爭力輔導團-AI工具庫(上架與導入補助) | G9: =IF(COUNTIF(比對結果!$G$2:$G$80,A9)>0,"✓","") | H9: 已盤點397項符合資安規範的AI工具;獲輔導企業導入工具庫方案可獲補助;審查重點為AI規格性能、資安保護、維運保證 | I9: 10 | J9: 每家企業AI工具導入補助最高10萬 | K9: 補助 | L9: 企業(需先完成診斷);AI工具商可申請上架 | M9: 是 | N9: 46711 | O9: 工具商上架受理至116年11月20日18:00(搜尋摘要) | Q9: =IF(ISNUMBER(N9),IF(N9<統計!$B$2,"已截止","受理中"),P9) -> 受理中 | R9: =IF(ISNUMBER(N9),N9-統計!$B$2,"") -> 396 | S9: 部分核對 | T9: 補助最高10萬與397項工具已由官方PDF、中央社核對;上架截止日僅取自搜尋摘要(產業署網頁禁止擷取) | U9: https://ida.gov.tw/ctlr?PRO=news.NewsView&id=43292&type=Insights
A10: 9 | B10: 第一則(經濟部) | C10: 工具、算力或平台 | D10: 經濟部 | E10: 產業發展署(中國生產力中心執行) | F10: 雲市集工業館-AI工具庫點數補助計畫 | G10: =IF(COUNTIF(比對結果!$G$2:$G$80,A10)>0,"✓","") | H10: 補助中小型製造業採購上架於雲市集工業館的AI應用方案;1點折抵1元,至多折抵一半服務費 | I10: 15 | J10: 每家最高15萬點(1點=1元) | K10: 點數折抵 | L10: 中小型製造業(須工廠登記) | M10: 限特定對象 | O10: 官方公告受理至2026-10-30 17:30,但有報導稱點數已於2026-07用罄 | P10: 未確認(可能已用罄) | Q10: =IF(ISNUMBER(N10),IF(N10<統計!$B$2,"已截止","受理中"),P10) -> 未確認(可能已用罄) | R10: =IF(ISNUMBER(N10),N10-統計!$B$2,"") | S10: 部分核對 | T10: 中小企業處頁面核對期限與資格;輔導資源查詢頁卻顯示受理至117年10月20日,兩官方頁不一致;「點數用罄」僅見單一部落格,請向產發署確認是否仍可申請 | U10: https://www.sme.gov.tw/caas/article-caas-3059-20513
A11: 10 | B11: 第一則(經濟部) | C11: 導入輔導與補助 | D11: 經濟部 | E11: 中小及新創企業署 | F11: 提升中小企業智慧化經營效能計畫(診斷、AI應用教案、AI導入應用輔導) | G11: =IF(COUNTIF(比對結果!$G$2:$G$80,A11)>0,"✓","") | H11: 115年度三大措施;AI導入應用輔導由資訊軟體協會執行,每案輔導總經費最高350萬、每家35,000元、每案帶動60至100家 | I11: 350 | J11: 每案輔導總經費(含稅) | K11: 輔導(法人或企業提案) | L11: 法人、公協會或企業提案;受輔導者為中小企業 | M11: 限特定對象 | N11: 46091 | O11: 線上提案至2026-03-10 17:00;執行至2026-11-15 | Q11: =IF(ISNUMBER(N11),IF(N11<統計!$B$2,"已截止","受理中"),P11) -> 已截止 | R11: =IF(ISNUMBER(N11),N11-統計!$B$2,"") -> -224 | S11: 已核對(官方) | T11: 經濟部新聞與115年度申請須知核對;已截止 | U11: https://www.moea.gov.tw/MNS/populace/news/News.aspx?kind=1&menu_id=40&news_id=121811
A12: 11 | B12: 第一則(經濟部) | C12: 導入輔導與補助 | D12: 經濟部 | E12: 中小及新創企業署(資策會窗口) | F12: 中小微企業AI創新應用輔導計畫 | G12: =IF(COUNTIF(比對結果!$G$2:$G$80,A12)>0,"✓","") | H12: 針對高成長潛力中小型製造與服務業提供AI深入輔導,以大帶小 | J12: 頁面未載金額 | K12: 輔導 | L12: 中小企業 | M12: 是 | O12: 頁面更新日2026-06-24,未載申請期間 | P12: 未確認 | Q12: =IF(ISNUMBER(N12),IF(N12<統計!$B$2,"已截止","受理中"),P12) -> 未確認 | R12: =IF(ISNUMBER(N12),N12-統計!$B$2,"") | S12: 部分核對 | T12: 官方頁核對輔導性質與對象;金額與申請期間未載 | U12: https://www.sme.gov.tw/article-tw-2877-13891
A13: 12 | B13: 第一則(經濟部) | C13: 導入輔導與補助 | D13: 經濟部 | E13: 商業發展署 | F13: 服務業AI升級(服務業韌性):單店、多店、整合型 | G13: =IF(COUNTIF(比對結果!$G$2:$G$80,A13)>0,"✓","") | H13: 單店導入AI工具;20至50家連鎖或加盟;跨至少3處場域的AI軟硬體整合 | I13: 2000 | J13: 單店最高10萬(補助50%);多店最高300萬;整合型最高2,000萬 | K13: 補助 | L13: 商業服務業店家、連鎖品牌 | M13: 是 | N13: 46680 | O13: 單店受理至2027-10-20或經費用罄(二手整理) | Q13: =IF(ISNUMBER(N13),IF(N13<統計!$B$2,"已截止","受理中"),P13) -> 受理中 | R13: =IF(ISNUMBER(N13),N13-統計!$B$2,"") -> 365 | S13: 部分核對 | T13: 10萬/300萬/2,000萬多家媒體一致;受理期間僅見二手資料;另有2025-12報導寫「2,000萬至3,000萬」,金額定義有出入,請以商發署公告為準 | U13: https://www.cio.com.tw/115430/
A14: 13 | B14: 第一則(經濟部) | C14: 工具、算力或平台 | D14: 經濟部 | E14: 中小及新創企業署 | F14: SME AI平台與中小企業網路大學校 | G14: =IF(COUNTIF(比對結果!$G$2:$G$80,A14)>0,"✓","") -> ✓ | H14: 整合可信AI工具與服務入口;網路大學校AI專區課程(媒體報導近200門) | J14: 免費資源,無補助金額 | K14: 平台與課程 | L14: 中小企業主與員工 | M14: 是 | O14: 常態開放 | P14: 常態開放 | Q14: =IF(ISNUMBER(N14),IF(N14<統計!$B$2,"已截止","受理中"),P14) -> 常態開放 | R14: =IF(ISNUMBER(N14),N14-統計!$B$2,"") | S14: 部分核對 | T14: 中企署簡報(2025-03)載AI課程91門,2026媒體報導近200門,課程數隨時間增加;未逐一核對平台現況。你提供的115年方案彙整表載明「中小企業網路大學校計畫(AI主題課程)」補助:單一企業最高15萬、聯合型最高30萬,受理至2026-07-31 17:00(經費用罄可提前截止),此補助應已截止;平台本身是否仍開放未另行核對 | U14: https://www.sme.gov.tw/drsme/drsme/Plan/plan_more?id=176a4cbd88b840358f46314988b1c408
A15: 14 | B15: 第二則(其他部會) | C15: 研發補助與投資 | D15: 數位發展部 | E15: 數位產業署 | F15: AI創新服務研發補助計畫(115年) | G15: =IF(COUNTIF(比對結果!$G$2:$G$80,A15)>0,"✓","") -> ✓ | H15: 協助軟體與資訊服務業者開發可產品化、可擴散的AI服務,協助中小企業降成本 | I15: 2000 | J15: AI Agent整合服務最高2,000萬;AI創新應用服務最高500萬;不超過總經費50%;每企業限1案 | K15: 現金補助 | L15: 軟體與資訊服務業者 | M15: 限特定對象 | N15: 46227 | O15: 申請至2026-07-24 16:59:59(DIGITAL+平台);計畫期程至2026-11-16或2027-11-16 | Q15: =IF(ISNUMBER(N15),IF(N15<統計!$B$2,"已截止","受理中"),P15) -> 已截止 | R15: =IF(ISNUMBER(N15),N15-統計!$B$2,"") -> -88 | S15: 部分核對 | T15: 更正:先前回答把計畫期程當成期限;實際申請截止為2026-07-24,已截止。來源為輔導顧問網站,未取得數發部原公告。與你提供的115年中小企業競爭力方案彙整表一致(申請至2026-07-24、上限500萬/2,000萬、期程至2026-11-16) | U15: https://www.jfetek.com/news/6
A16: 15 | B16: 第二則(其他部會) | C16: 研發補助與投資 | D16: 數位發展部 | E16: 數位產業署 | F16: AI領航推動計畫(112–114年) | G16: =IF(COUNTIF(比對結果!$G$2:$G$80,A16)>0,"✓","") | H16: 協助企業開發AI創新應用並落地商轉 | I16: 2000 | J16: 112年徵案每案最高2,000萬,不超過總經費50% | K16: 現金補助 | L16: 企業 | M16: 是 | O16: 官方頁載執行至114年底 | P16: 已結束 | Q16: =IF(ISNUMBER(N16),IF(N16<統計!$B$2,"已截止","受理中"),P16) -> 已結束 | R16: =IF(ISNUMBER(N16),N16-統計!$B$2,"") | S16: 部分核對 | T16: 官方頁確認執行至114年底;2,000萬為2023年徵案報導數字;115年後續計畫未查到 | U16: https://moda.gov.tw/major-policies/ai/industry/19254
A17: 16 | B17: 第二則(其他部會) | C17: 導入輔導與補助 | D17: 數位發展部 | E17: 數位發展署 | F17: 導入AI應用實作計畫 | G17: =IF(COUNTIF(比對結果!$G$2:$G$80,A17)>0,"✓","") | H17: 由資訊軟體協會執行,以工作坊協助各行業中小企業導入AI | J17: 未查到 | K17: 工作坊輔導 | L17: 中小企業 | M17: 是 | O17: 未查到 | P17: 未確認 | Q17: =IF(ISNUMBER(N17),IF(N17<統計!$B$2,"已截止","受理中"),P17) -> 未確認 | R17: =IF(ISNUMBER(N17),N17-統計!$B$2,"") | S17: 僅媒體或二手 | T17: 僅見校方轉載2026-01新聞,金額與期限未查到 | U17: https://aict.nkust.edu.tw/digitrans/?cat=566
A18: 17 | B18: 第二則(其他部會) | C18: 研發補助與投資 | D18: 數位發展部 | E18: 數位發展部 | F18: 加強投資AI新創實施方案 | G18: =IF(COUNTIF(比對結果!$G$2:$G$80,A18)>0,"✓","") | H18: 100億元基金投資AI新創;截至2026年2月已核定6案,帶動民間投資逾3億元 | J18: 基金規模100億元,非每案上限 | K18: 投資 | L18: AI新創 | M18: 限特定對象 | O18: 未查到 | P18: 未確認 | Q18: =IF(ISNUMBER(N18),IF(N18<統計!$B$2,"已截止","受理中"),P18) -> 未確認 | R18: =IF(ISNUMBER(N18),N18-統計!$B$2,"") | S18: 僅媒體或二手 | T18: 僅鉅亨/優分析報導(引述數發部),未取得官方公告 | U18: https://uanalyze.com.tw/articles/1078148404
A19: 18 | B19: 第二則(其他部會) | C19: 研發補助與投資 | D19: 國科會 | E19: 經濟部商業發展署(協辦) | F19: 智慧雨林產業創生補助-AI中央廚房(大南方新矽谷) | G19: =IF(COUNTIF(比對結果!$G$2:$G$80,A19)>0,"✓","") | H19: 聚焦中央廚房與智慧餐廚場域;商業服務業者、資服業者、大專校院三方合作;場域限嘉義、臺南、高雄、屏東 | I19: 3000 | J19: 業者每年每案最高3,000萬;大專院校每年每案500萬;期程兩年 | K19: 現金補助 | L19: 中央廚房營運業者(主提案者) | M19: 限特定對象 | O19: 115年度徵案2025-12-05至2026-01-20已截止;2026-04報導稱再次徵案,日期未載 | P19: 未確認 | Q19: =IF(ISNUMBER(N19),IF(N19<統計!$B$2,"已截止","受理中"),P19) -> 未確認 | R19: =IF(ISNUMBER(N19),N19-統計!$B$2,"") | S19: 部分核對 | T19: 徵案公告(校方轉載)與工商時報金額一致;再次徵案的期限未能確認 | U19: https://news.stust.edu.tw/id/91744
A20: 19 | B20: 第二則(其他部會) | C20: 研發補助與投資 | D20: 農業部 | E20: 農業部 | F20: AI導入農漁畜智能模組研發與建構(115–116年度) | G20: =IF(COUNTIF(比對結果!$G$2:$G$80,A20)>0,"✓","") | H20: 建構病蟲害判識、智慧栽培養殖等公版模組 | J20: 公告摘要未載金額 | K20: 研發委託 | L20: 大專校院團隊 | M20: 否 | N20: 45954 | O20: 徵求期間2025-10-03至2025-10-24 | Q20: =IF(ISNUMBER(N20),IF(N20<統計!$B$2,"已截止","受理中"),P20) -> 已截止 | R20: =IF(ISNUMBER(N20),N20-統計!$B$2,"") -> -361 | S20: 部分核對 | T20: 校方轉載農業部徵求公告,已截止;企業不是主要申請者 | U20: https://news.stust.edu.tw/id/90940
A21: 20 | B21: 第二則(其他部會) | C21: 研發補助與投資 | D21: 衛生福利部 | E21: 資訊處 | F21: 第二、三類AI中心補助計畫(115年) | G21: =IF(COUNTIF(比對結果!$G$2:$G$80,A21)>0,"✓","") | H21: 補助醫院的臨床AI取證驗證中心與AI影響性研究中心 | I21: 750 | J21: 每案500萬或750萬(公告未說明各適用對象);全案預算5,750萬 | K21: 現金補助 | L21: 完成114年度「次世代數位醫療平臺」三大AI中心計畫的醫院 | M21: 否 | N21: 46286 | O21: 受理至2026-09-21 17:00;執行期365日 | Q21: =IF(ISNUMBER(N21),IF(N21<統計!$B$2,"已截止","受理中"),P21) -> 已截止 | R21: =IF(ISNUMBER(N21),N21-統計!$B$2,"") -> -29 | S21: 已核對(官方) | T21: 衛福部官方頁核對;更正:已截止,且對象限特定醫院 | U21: https://www.mohw.gov.tw/cp-7283-87899-1.html
A22: 21 | B22: 第二則(其他部會) | C22: 工具、算力或平台 | D22: 數位發展部 | E22: 數位產業署 | F22: AI算力平台 | G22: =IF(COUNTIF(比對結果!$G$2:$G$80,A22)>0,"✓","") | H22: 免費提供NVIDIA、AMD GPU算力;點數制(訓練1點=0.5 GPU小時),使用期三個月;禁用中國來源開源模型(如DeepSeek) | J22: 免費,訓練類L1/L2/L3為1,000/2,000/6,000點 | K22: 免費資源 | L22: 數位經濟產業業者(軟體、資訊服務、電商、第三方支付等),成立未滿8年新創優先 | M22: 限特定對象 | N22: 46325 | O22: 申請至2026-10-30 23:59,線上申請需工商憑證 | Q22: =IF(ISNUMBER(N22),IF(N22<統計!$B$2,"已截止","受理中"),P22) -> 受理中 | R22: =IF(ISNUMBER(N22),N22-統計!$B$2,"") -> 10 | S22: 已核對(官方) | T22: 2026-08-14版申請須知核對;更正:資格不只資服與新創,涵蓋多類數位經濟產業 | U22: https://www-api.moda.gov.tw/File/Get/adi/zh-tw/owvBgtTcGlT8cjT
A23: 22 | B23: 第二則(其他部會) | C23: 工具、算力或平台 | D23: 數位發展部 | E23: 數位發展部 | F23: 台灣主權AI訓練語料庫 | G23: =IF(COUNTIF(比對結果!$G$2:$G$80,A23)>0,"✓","") | H23: 累積逾11億個Token,逾200個政府機關參與 | J23: 資料資源,無金額 | K23: 資料資源 | L23: 公部門與研究機構為主 | M23: 限特定對象 | O23: 未查到 | P23: 未確認 | Q23: =IF(ISNUMBER(N23),IF(N23<統計!$B$2,"已截止","受理中"),P23) -> 未確認 | R23: =IF(ISNUMBER(N23),N23-統計!$B$2,"") | S23: 僅媒體或二手 | T23: 僅媒體報導(引述數發部),企業使用條件未查到 | U23: https://uanalyze.com.tw/articles/1078148404
A24: 23 | B24: 第二則(其他部會) | C24: 工具、算力或平台 | D24: 數位發展部 | E24: 數位產業署 | F24: 臺灣雲市集 TCloud | G24: =IF(COUNTIF(比對結果!$G$2:$G$80,A24)>0,"✓","") | H24: 提供雲端工具;官網公告因計畫結束及政策調整,服務將配合調整 | J24: 未核對(二手資料提及3萬點) | K24: 點數折抵 | L24: 不限產業 | M24: 是 | O24: 計畫結束中,日期未載 | P24: 未確認(計畫結束中) | Q24: =IF(ISNUMBER(N24),IF(N24<統計!$B$2,"已截止","受理中"),P24) -> 未確認(計畫結束中) | R24: =IF(ISNUMBER(N24),N24-統計!$B$2,"") | S24: 僅媒體或二手 | T24: 僅見部落格轉述官網公告,本次未能讀取官網 | U24: https://www.yutuo-tech.com/blog/ai-subsidy-2026/
A25: 24 | B25: 第二則(其他部會) | C25: 工具、算力或平台 | D25: 國科會 | E25: 國科會 | F25: 大南方AI算力與TAIDE | G25: =IF(COUNTIF(比對結果!$G$2:$G$80,A25)>0,"✓","") | H25: 提升算力並精進臺版大型語言模型TAIDE,發展主權AI | J25: 無金額 | K25: 研究與生態系資源 | L25: 研究機構與生態系 | M25: 未確認 | O25: 未查到 | P25: 未確認 | Q25: =IF(ISNUMBER(N25),IF(N25<統計!$B$2,"已截止","受理中"),P25) -> 未確認 | R25: =IF(ISNUMBER(N25),N25-統計!$B$2,"") | S25: 僅媒體或二手 | T25: 依2025-01 iThome報導,為政策規劃,企業使用方式未查到 | U25: https://www.ithome.com.tw/news/167005
A26: 25 | B26: 第二則(其他部會) | C26: AI人才培訓 | D26: 勞動部 | E26: 勞動力發展署 | F26: 產業新尖兵計畫 | G26: =IF(COUNTIF(比對結果!$G$2:$G$80,A26)>0,"✓","") | H26: AI相關訓練課程;每人另有最高9.6萬學習獎勵金 | I26: 10 | J26: 每人最高10萬課程費補助 | K26: 課程費補助 | L26: 15至29歲失業或待業青年 | M26: 否 | O26: 未查到 | P26: 未確認 | Q26: =IF(ISNUMBER(N26),IF(N26<統計!$B$2,"已截止","受理中"),P26) -> 未確認 | R26: =IF(ISNUMBER(N26),N26-統計!$B$2,"") | S26: 僅媒體或二手 | T26: 依113年新聞,現行辦法未取得 | U26: https://www.1111.com.tw/news/jobns/157396
A27: 26 | B27: 第二則(其他部會) | C27: AI人才培訓 | D27: 勞動部 | E27: 勞動力發展署 | F27: 產業人才投資方案 | G27: =IF(COUNTIF(比對結果!$G$2:$G$80,A27)>0,"✓","") | H27: 在職勞工AI等重點產業課程 | I27: 7 | J27: 每人3年內最高7萬(舊新聞數字) | K27: 課程費補助 | L27: 在職勞工 | M27: 否 | O27: 未查到 | P27: 未確認 | Q27: =IF(ISNUMBER(N27),IF(N27<統計!$B$2,"已截止","受理中"),P27) -> 未確認 | R27: =IF(ISNUMBER(N27),N27-統計!$B$2,"") | S27: 僅媒體或二手 | T27: 依2023年新聞,現行額度請查勞動力發展署 | U27: https://www.1111.com.tw/news/jobns/156631

Sheet 115年方案彙整
A1: 編號 | B1: 來源回答 | C1: 類別 | D1: 主辦部會 | E1: 執行/主管單位 | F1: 計畫或資源名稱 | G1: 完整版已收錄 | H1: 完整版編號 | I1: 115年中小企業競爭力方案 | J1: 內容重點 | K1: 補助上限(萬元) | L1: 上限定義 | M1: 補助型態 | N1: 申請對象 | O1: 企業可直接申請? | P1: 申請截止日 | Q1: 期限說明 | R1: 無截止日時的狀態 | S1: 申請狀態 | T1: 距截止天數 | U1: 查證結果 | V1: 核對說明與更正 | W1: 資料來源 | X1: 上傳清單列號
A2: 1 | B2: 上傳清單(經濟部115年方案) | D2: 經濟部 | E2: 數位產業署 | F2: 115年度AI創新服務研發補助計畫 | G2: =IF(H2<>"","✓","") -> ✓ | H2: =IF(INDEX(比對結果!$G$2:$G$42,MATCH(X2,比對結果!$A$2:$A$42,0))="","",INDEX(比對結果!$G$2:$G$42,MATCH(X2,比對結果!$A$2:$A$42,0))) -> 14 | I2: ✓ | V2: 已收錄於「計畫總表」,資料與狀態請見該表對應編號 | X2: 2
A3: 2 | B3: 上傳清單(經濟部115年方案) | C3: 研發補助與投資 | D3: 經濟部 | E3: 產業技術司 | F3: A+企業創新研發淬鍊計畫－前瞻技術創業投資計畫(A+STEP) | G3: =IF(H3<>"","✓","") | H3: =IF(INDEX(比對結果!$G$2:$G$42,MATCH(X3,比對結果!$A$2:$A$42,0))="","",INDEX(比對結果!$G$2:$G$42,MATCH(X3,比對結果!$A$2:$A$42,0))) | I3: ✓ | J3: 藉由新創事業熟悉之募資程序，引導法人創投進行專業投資評估，並以商業機制決定補助對象，透過推動本計畫促成法人創投與獲投之新創事業投入前瞻技術開發，並輔以法人創投能量加速落實商業應用。 | K3: 3000 | L3: 2年最高3,000萬元（補助比例≤40%）；新創成立3年內加碼20%後(補助比例 ≤50%) | M3: 研發投資補助款 | N3: 法人創投；＋國內成立8年內之新創事業 | O3: 限特定對象 | P3: 46387 | Q3: 115/1/1-115/12/31；企業執行期間:計畫申請時程：自公告日起算1個月後開始受理收件；計畫執行期程原則不超過2年 | S3: =IF(ISNUMBER(P3),IF(P3<統計!$B$2,"已截止","受理中"),R3) -> 受理中 | T3: =IF(ISNUMBER(P3),P3-統計!$B$2,"") -> 72 | U3: 僅上傳清單(未獨立核對) | V3: 2年最高3,000萬(補助≤40%);新創成立3年內加碼20%(≤50%)。受理期間為2026全年(自公告日起算1個月後開始收件) | W3: https://service.moea.gov.tw/EE514/tw/aiip/147.html | X3: 4
A4: 3 | B4: 上傳清單(經濟部115年方案) | C4: 導入輔導與補助 | D4: 經濟部 | E4: 產業技術司 | F4: 2026年國際鏈結與商業概念驗證專案 | G4: =IF(H4<>"","✓","") | H4: =IF(INDEX(比對結果!$G$2:$G$42,MATCH(X4,比對結果!$A$2:$A$42,0))="","",INDEX(比對結果!$G$2:$G$42,MATCH(X4,比對結果!$A$2:$A$42,0))) | I4: ✓ | J4: 為協助國內科技專案衍生新創公司及具國際發展潛力之臺灣科研新創鏈結國際創新創業資源，本專案整合工研院矽谷資源，槓桿Berkeley SkyDeck與Stanford University能量，遴選具潛力新創公司赴美進行3個月商業概念驗證與商務拓展，串接國際新創生態圈與展會資源，開拓全球市場機會。 | K4: 180 | L4: 180萬元（含稅）為上限；分二期撥付（簽約65%、驗收後35%） | M4: 國際商務拓展輔導及專案執行費補助（赴美3個月商業概念驗證與商務拓展） | N4: 2018年1月1日後依法登記成立之新創公司，屬(1)執行科技專案計畫衍生新創公司，或(2)臺灣科研新創公司（具潛力型或領導型技術）之一 | O4: 限特定對象 | P4: 46078 | Q4: 115/01/30-115/02/25；12:00PM止；企業執行期間:簽約後執行至2026年9月30日前完成履約項目並提交期末報告 | S4: =IF(ISNUMBER(P4),IF(P4<統計!$B$2,"已截止","受理中"),R4) -> 已截止 | T4: =IF(ISNUMBER(P4),P4-統計!$B$2,"") -> -237 | U4: 僅上傳清單(未獨立核對) | V4: 受理至2026-02-25 12:00;180萬元含稅,分二期撥付 | W4: https://tree.meetbao.net/2026/01/2026%e5%b9%b4%e5%9c%8b%e9%9a%9b%e9%8f%88%e7%b5%90%e8%88%87%e5%95%86%e6%a5%ad%e6%a6%82%e5%bf%b5%e9%a9%97%e8%ad%89%e5%b0%88%e6%a1%88landing-program%e5%be%b5/ | X4: 5
A5: 4 | B5: 上傳清單(經濟部115年方案) | C5: 導入輔導與補助 | D5: 經濟部 | E5: 產業技術司 | F5: 2026年國際鏈結與商業概念驗證專案（TREE Landing Program）第二次擴大徵案 | G5: =IF(H5<>"","✓","") | H5: =IF(INDEX(比對結果!$G$2:$G$42,MATCH(X5,比對結果!$A$2:$A$42,0))="","",INDEX(比對結果!$G$2:$G$42,MATCH(X5,比對結果!$A$2:$A$42,0))) | I5: ✓ | J5: 為擴大科專新創籌備團隊參與國際創新創業生態圈，整合工研院矽谷資源，槓桿Berkeley SkyDeck與Stanford University能量，遴選具國際發展潛力之法人新創團隊赴美進行3個月商業概念驗證與商務拓展，串接矽谷新創生態圈與國際展會資源，開拓全球市場機會。 | K5: 180 | L5: 180萬元（含稅）為上限；分二期撥付（簽約65%、驗收後35%） | M5: 國際商務拓展輔導及專案執行費補助（赴美3個月商業概念驗證與商務拓展） | N5: 執行經濟部科技專案計畫之法人機構，預計兩年內（2028年3月前）完成國內公司設立之法人新創團隊 | O5: 限特定對象 | P5: 46101 | Q5: 115/03/10-115/03/20；12:00PM止；企業執行期間:簽約後執行至2026年9月30日前完成履約項目並提交期末報告 | S5: =IF(ISNUMBER(P5),IF(P5<統計!$B$2,"已截止","受理中"),R5) -> 已截止 | T5: =IF(ISNUMBER(P5),P5-統計!$B$2,"") -> -214 | U5: 僅上傳清單(未獨立核對) | V5: 受理至2026-03-20 12:00;對象為執行經濟部科專的法人新創團隊 | W5: https://tree.meetbao.net/2026/03/2026landing-program-2/ | X5: 6
A6: 5 | B6: 上傳清單(經濟部115年方案) | C6: 非對外公告(委辦/採購) | D6: 經濟部 | E6: 國際貿易署 | F6: 中小企業數據貿易平台建置案(委辦/採購案) | G6: =IF(H6<>"","✓","") | H6: =IF(INDEX(比對結果!$G$2:$G$42,MATCH(X6,比對結果!$A$2:$A$42,0))="","",INDEX(比對結果!$G$2:$G$42,MATCH(X6,比對結果!$A$2:$A$42,0))) | I6: ✓ | J6: 以建置數據貿易平台與相關服務為主，已註記為平台建置案；通常透過政府採購或委辦方式辦理，不是一般企業可申請的補助方案。 | L6: 依採購預算與契約 | M6: 不適用（委辦／採購） | N6: 具相關能力之採購投標廠商 | O6: 否 | Q6: 依政府採購／委辦公告；企業執行期間:依採購契約期程 | R6: 非申請制 | S6: =IF(ISNUMBER(P6),IF(P6<統計!$B$2,"已截止","受理中"),R6) -> 非申請制 | T6: =IF(ISNUMBER(P6),P6-統計!$B$2,"") | U6: 僅上傳清單(未獨立核對) | V6: 上傳清單載明為平台建置委辦/採購案,非對外公告的政策資源 | W6: https://www.aieztrade.com/ | X6: 7
A7: 6 | B7: 上傳清單(經濟部115年方案) | C7: 導入輔導與補助 | D7: 經濟部 | E7: 國際貿易署 | F7: 運用數位新貿易模式計畫 | G7: =IF(H7<>"","✓","") | H7: =IF(INDEX(比對結果!$G$2:$G$42,MATCH(X7,比對結果!$A$2:$A$42,0))="","",INDEX(比對結果!$G$2:$G$42,MATCH(X7,比對結果!$A$2:$A$42,0))) | I7: ✓ | J7: 為提升我國出口業者之數位能力，推動運用數位新貿易模式計畫，提供完整「數位診斷 → 顧問諮詢 → 輔導方案 → 培訓課程」整合服務，透過AI × 數據導入，啟動中小企業拓銷動能，協助我出口業者應用數位科技工具拓展海外市場，以加速爭取國際商機。 | L7: 無 | M7: 數位診斷 / 顧問諮詢 / 輔導方案 / 培訓課程 | N7: 有跨境貿易或數位貿易需求之業者 | O7: 是 | Q7: 自公告日起至115年9月30日或經費用罄之日止，下午6時前完成線上申請；企業執行期間:顧問諮詢：申請至115年10月30日止；輔導方案：申請至115年9月30日止；課程：115年12月31日止 | R7: 未確認(分項期限不同) | S7: =IF(ISNUMBER(P7),IF(P7<統計!$B$2,"已截止","受理中"),R7) -> 未確認(分項期限不同) | T7: =IF(ISNUMBER(P7),P7-統計!$B$2,"") | U7: 部分核對 | V7: 【名稱或簡述提到AI】各項期限不同:輔導方案申請至2026-09-30(已過)、顧問諮詢申請至2026-10-30(尚在期限內)、課程至2026-12-31;專案網站載明申請免費、輔導方案共8個,但未載期限,上傳清單金額欄為「無」 | W7: https://newtrade.aieztrade.com/ | X7: 8
A8: 7 | B8: 上傳清單(經濟部115年方案) | C8: 導入輔導與補助 | D8: 經濟部 | E8: 商業發展署 | F8: 115年度「商業服務業數據驅動價值創造計畫」輔導案 | G8: =IF(H8<>"","✓","") | H8: =IF(INDEX(比對結果!$G$2:$G$42,MATCH(X8,比對結果!$A$2:$A$42,0))="","",INDEX(比對結果!$G$2:$G$42,MATCH(X8,比對結果!$A$2:$A$42,0))) | I8: ✓ | J8: 為促進服務業智慧轉型，協助業者導入AI應用、多模態AI（Multimodal AI）與AI代理（AI Agent）等前瞻技術，整合內外部數據與智慧流程自動化，將商業資料轉化為可行動洞察與即時決策能力，進而提升營運效率與決策品質，並以AI 驅動服務創新與商業模式升級、拓展國際市場 | K8: 600 | L8: 1.提案計畫總經費請列明輔導款與自籌款兩部分，輔導款不得超過全案總經費之50%；最高可申請之輔導款額度，以新臺幣600萬元為上限(實際輔導金額依審查結果核定之)；2.公司實收資本額不得低於自籌款，自籌款不得低於輔導款，亦即輔導款 ≦ 自籌款 ≦ 實收資本額。 | M8: 輔導(有輔導款) | N8: 依公司法登記之公司，且實際從事商業服務業（批發、零售、物流、餐飲、休憩服務、生活服務業） | O8: 是 | P8: 46126 | Q8: 115/03/17-115/04-14；企業執行期間:自遴選結果公告於「經濟部商業發展署」網站（https://www.aoc.gov.tw/）之日起至115年11月20日止。 | S8: =IF(ISNUMBER(P8),IF(P8<統計!$B$2,"已截止","受理中"),R8) -> 已截止 | T8: =IF(ISNUMBER(P8),P8-統計!$B$2,"") -> -189 | U8: 僅上傳清單(未獨立核對) | V8: 【名稱或簡述提到AI】輔導款上限600萬,不超過全案總經費50%;輔導款≦自籌款≦實收資本額 | W8: https://www.moea.gov.tw/Mns/populace/news/News.aspx?kind=2&menu_id=41&news_id=122129 | X8: 9
A9: 8 | B9: 上傳清單(經濟部115年方案) | C9: 導入輔導與補助 | D9: 經濟部 | E9: 商業發展署 | F9: 街區品牌特色發展計畫 | G9: =IF(H9<>"","✓","") | H9: =IF(INDEX(比對結果!$G$2:$G$42,MATCH(X9,比對結果!$A$2:$A$42,0))="","",INDEX(比對結果!$G$2:$G$42,MATCH(X9,比對結果!$A$2:$A$42,0))) | I9: ✓ | J9: 依據街區發展文化形塑街區品牌特色，打造商業群聚新意象，輔導街店導入智慧商業應用與全通路行銷，提升科技能量，聚焦街區特色並深化顧客體驗，帶動小型商業創新發展。 | L9: 不適用 | M9: 輔導(無輔導款) | N9: 商業服務業 | O9: 未確認 | Q9: 不適用 | R9: 未確認 | S9: =IF(ISNUMBER(P9),IF(P9<統計!$B$2,"已截止","受理中"),R9) -> 未確認 | T9: =IF(ISNUMBER(P9),P9-統計!$B$2,"") | U9: 僅上傳清單(未獨立核對) | V9: 上傳清單的受理期間、方式、金額均標示「不適用」 | X9: 10
A10: 9 | B10: 上傳清單(經濟部115年方案) | C10: 導入輔導與補助 | D10: 經濟部 | E10: 商業發展署 | F10: 115年度「老店創生輔導」 | G10: =IF(H10<>"","✓","") | H10: =IF(INDEX(比對結果!$G$2:$G$42,MATCH(X10,比對結果!$A$2:$A$42,0))="","",INDEX(比對結果!$G$2:$G$42,MATCH(X10,比對結果!$A$2:$A$42,0))) | I10: ✓ | J10: 為協助臺灣老店提升數位應用能力，透過數位工具協助營運、市場分析、行銷、產品開發及各項服務，以靈活因應新世代市場趨勢與消費需求，並透過數位科技串聯品牌獨有之歷史文化與場域氛圍，開發創新產品與服務，進一步強化老店競爭優勢，促進永續經營與穩健成長 | K10: 40 | L10: 1.一般輔導：含1次顧問申請計畫書診斷、2次輔導會議、專屬線上輔導LINE群組，輔導金額新台幣8萬元。；2.標竿輔導：含1次顧問申請計畫書診斷、2次輔導會議、專屬線上輔導LINE群組，輔導金額新台幣40萬元。 | M10: 輔導 / (有輔導款) / (無輔導款) | N10: 在我國經營60年（含）以上，並依我國公司法或商業登記法完成設立，有實體零售或服務門店業者。 | O10: 限特定對象 | P10: 46203 | Q10: 115/06/09-115/06/30；企業執行期間:簽約日115年8月21日起至115年10月31日止。 | S10: =IF(ISNUMBER(P10),IF(P10<統計!$B$2,"已截止","受理中"),R10) -> 已截止 | T10: =IF(ISNUMBER(P10),P10-統計!$B$2,"") -> -112 | U10: 僅上傳清單(未獨立核對) | V10: 一般輔導8萬、標竿輔導40萬(上限填標竿輔導);限經營60年以上老店 | W10: https://www.aoc.gov.tw/showPublic/700 | X10: 11
A11: 10 | B11: 上傳清單(經濟部115年方案) | C11: 導入輔導與補助 | D11: 經濟部 | E11: 商業發展署 | F11: 115年度「推動餐飲服務業優質成長暨國際推廣計畫」產品開發試銷輔導 | G11: =IF(H11<>"","✓","") | H11: =IF(INDEX(比對結果!$G$2:$G$42,MATCH(X11,比對結果!$A$2:$A$42,0))="","",INDEX(比對結果!$G$2:$G$42,MATCH(X11,比對結果!$A$2:$A$42,0))) | I11: ✓ | J11: 協助餐飲業者開發適合商品化之產品，打造臺灣特色美食商品化及標準化之能力，將產品上架於國內或國外通路。 | L11: 一、國內市場：每案配合款上限為新臺幣40萬元。；二、海外市場：每案配合款上限為新臺幣60萬元。；三、產品開發試銷輔導之廠商配合款不可少於政府輔導款金額1/2。；四、本款項不得用於採購中國品牌之軟硬體產品或服務。 | M11: 輔導 / (有輔導款) / (無輔導款) | N11: 一、 以餐點具備臺灣美食特色之餐飲業者為主，已有品牌且至少須有1家實體店面。；二、 體系輔導可聯合非餐飲之業者，至少6家以上來共同進行申請，但每案之餐飲業者比例須至少1/2以上。 | O11: 限特定對象 | P11: 46136 | Q11: 115/04/01-115/04/24；企業執行期間:自評選通過簽約後至115年11月15日止。 | S11: =IF(ISNUMBER(P11),IF(P11<統計!$B$2,"已截止","受理中"),R11) -> 已截止 | T11: =IF(ISNUMBER(P11),P11-統計!$B$2,"") -> -179 | U11: 僅上傳清單(未獨立核對) | V11: 上傳清單寫「配合款上限」國內40萬、海外60萬,未標示政府輔導款上限,故上限欄不填數值 | W11: https://www.moea.gov.tw/MNS/populace/news/News.aspx?kind=2&menu_id=41&news_id=122246 | X11: 12
A12: 11 | B12: 上傳清單(經濟部115年方案) | C12: 導入輔導與補助 | D12: 經濟部 | E12: 商業發展署 | F12: 115年度「推動餐飲服務業優質成長暨國際推廣計畫」通路拓展輔導 | G12: =IF(H12<>"","✓","") | H12: =IF(INDEX(比對結果!$G$2:$G$42,MATCH(X12,比對結果!$A$2:$A$42,0))="","",INDEX(比對結果!$G$2:$G$42,MATCH(X12,比對結果!$A$2:$A$42,0))) | I12: ✓ | J12: 協助餐飲業者建立海外輸出策略及模式等，進行品牌授權、海外代理或海外展店，增進業者落地經營能量，提升臺灣餐飲國際市場競爭實力。通路拓展方式可採海外展店或第三方合作（含海外代理、品牌授權等）。 | L12: 一、每案配合款上限為新臺幣80萬元。；二、通路拓展輔導之廠商配合款不可少於政府輔導款金額1/2。；三、本款項不得用於採購中國品牌之軟硬體產品或服務。 | M12: 輔導 / (有輔導款) / (無輔導款) | N12: 一、 以餐點具備臺灣美食特色之餐飲業者為主，已有品牌且至少須有1家實體店面。；二、 體系輔導可聯合非餐飲之業者，至少6家以上來共同進行申請，但每案之餐飲業者比例須至少1/2以上。 | O12: 限特定對象 | P12: 46136 | Q12: 115/04/01-115/04/24；企業執行期間:自評選通過簽約後至115年11月15日止。 | S12: =IF(ISNUMBER(P12),IF(P12<統計!$B$2,"已截止","受理中"),R12) -> 已截止 | T12: =IF(ISNUMBER(P12),P12-統計!$B$2,"") -> -179 | U12: 僅上傳清單(未獨立核對) | V12: 上傳清單寫「配合款上限」80萬,未標示政府輔導款上限,故上限欄不填數值 | W12: https://www.moea.gov.tw/MNS/populace/news/News.aspx?kind=2&menu_id=41&news_id=122246 | X12: 13
A13: 12 | B13: 上傳清單(經濟部115年方案) | C13: 導入輔導與補助 | D13: 經濟部 | E13: 商業發展署 | F13: 115年度「推動餐飲服務業優質成長暨國際推廣計畫」餐飲體系輔導 | G13: =IF(H13<>"","✓","") | H13: =IF(INDEX(比對結果!$G$2:$G$42,MATCH(X13,比對結果!$A$2:$A$42,0))="","",INDEX(比對結果!$G$2:$G$42,MATCH(X13,比對結果!$A$2:$A$42,0))) | I13: ✓ | J13: 協助餐飲業者品牌價值共創，由單點輸出轉型為系統化或模組化之團體營銷模式。以整合供應鏈與數位工具應用，建構具備品牌一致性與市場彈性的輔導體系，開發可複製、可擴散的新型商業模式，強化臺灣餐飲市場競爭力與品牌影響力。 | L13: 一、每案配合款上限為新臺幣200萬元。；二、廠商配合款不可少於政府輔導款金額1/4。；三、本款項不得用於採購中國品牌之軟硬體產品或服務。 | M13: 輔導 / (有輔導款) / (無輔導款) | N13: 一、 以餐點具備臺灣美食特色之餐飲業者為主，已有品牌且至少須有1家實體店面。；二、 體系輔導可聯合非餐飲之業者，至少6家以上來共同進行申請，但每案之餐飲業者比例須至少1/2以上。 | O13: 限特定對象 | P13: 46155 | Q13: 115/04/01-115/05/13；企業執行期間:自評選通過簽約後至115年11月15日止。 | S13: =IF(ISNUMBER(P13),IF(P13<統計!$B$2,"已截止","受理中"),R13) -> 已截止 | T13: =IF(ISNUMBER(P13),P13-統計!$B$2,"") -> -160 | U13: 僅上傳清單(未獨立核對) | V13: 上傳清單寫「配合款上限」200萬,未標示政府輔導款上限,故上限欄不填數值 | W13: https://www.moea.gov.tw/MNS/populace/news/News.aspx?kind=2&menu_id=41&news_id=122246 | X13: 14
A14: 13 | B14: 上傳清單(經濟部115年方案) | C14: 導入輔導與補助 | D14: 經濟部 | E14: 商業發展署 | F14: 115年度「推動餐飲服務業優質成長暨國際推廣計畫」餐廳雙語服務提升輔導 | G14: =IF(H14<>"","✓","") | H14: =IF(INDEX(比對結果!$G$2:$G$42,MATCH(X14,比對結果!$A$2:$A$42,0))="","",INDEX(比對結果!$G$2:$G$42,MATCH(X14,比對結果!$A$2:$A$42,0))) | I14: ✓ | J14: 協助餐飲店家完善中英雙語菜單、服務標示與接待流程，營造國際旅客友善用餐環境，透過示範場域建立與服務品質提升，提升餐飲服務品質。 | K14: 3 | L14: 依照業者實際需求搭配執行，必選及輔選項目申請金額合計上限為新臺幣3萬元。 | M14: 輔導 / (有輔導款) / (無輔導款) | N14: 一、鄰近國際展會、國際型場館周邊場域及捷運站點周邊為優先之餐飲門店。；二、至少開設1家實體店面，提供內用或外帶之餐飲業者。 | O14: 限特定對象 | P14: 46206 | Q14: 第一梯次：115/03/11-115/04/10；第二梯次：115/06/03-115/07/03；企業執行期間:核定日起至115年9月30日止 | S14: =IF(ISNUMBER(P14),IF(P14<統計!$B$2,"已截止","受理中"),R14) -> 已截止 | T14: =IF(ISNUMBER(P14),P14-統計!$B$2,"") -> -109 | U14: 僅上傳清單(未獨立核對) | V14: 分兩梯次:第一梯次至2026-04-10、第二梯次至2026-07-03;金額為申請金額合計上限3萬 | W14: https://www.aoc.gov.tw/showPublic/604 | X14: 15
A15: 14 | B15: 上傳清單(經濟部115年方案) | C15: 導入輔導與補助 | D15: 經濟部 | E15: 商業發展署 | F15: 115年度「糕餅業創新永續發展計畫」糕餅業深度輔導(單一企業申請) | G15: =IF(H15<>"","✓","") | H15: =IF(INDEX(比對結果!$G$2:$G$42,MATCH(X15,比對結果!$A$2:$A$42,0))="","",INDEX(比對結果!$G$2:$G$42,MATCH(X15,比對結果!$A$2:$A$42,0))) | I15: ✓ | J15: 透過推動升級優化體驗、創新體系之深度輔導，引導更多糕餅業主動提升產品力、服務力及國內外市場競爭力，以協助臺灣糕餅企業厚實經營基礎、促進糕餅產業升級。 | K15: 15 | L15: 每案政府輔導經費以15萬元（含稅）為上限，企業自籌款至少為政府輔導經費的30%（含稅） | M15: 輔導 / (有輔導款) / (無輔導款) | N15: 單一糕餅企業申請。 | O15: 限特定對象 | P15: 46139 | Q15: 115/03/02-115/04/27；企業執行期間:自簽約日起至115年11月30日止。 | S15: =IF(ISNUMBER(P15),IF(P15<統計!$B$2,"已截止","受理中"),R15) -> 已截止 | T15: =IF(ISNUMBER(P15),P15-統計!$B$2,"") -> -176 | U15: 僅上傳清單(未獨立核對) | V15: 名稱與下一列相同,依對象區分為單一企業申請;政府輔導經費上限15萬(含稅) | W15: https://www.aoc.gov.tw/showPublic/599 | X15: 16
A16: 15 | B16: 上傳清單(經濟部115年方案) | C16: 導入輔導與補助 | D16: 經濟部 | E16: 商業發展署 | F16: 115年度「糕餅業創新永續發展計畫」糕餅業深度輔導(體系申請) | G16: =IF(H16<>"","✓","") | H16: =IF(INDEX(比對結果!$G$2:$G$42,MATCH(X16,比對結果!$A$2:$A$42,0))="","",INDEX(比對結果!$G$2:$G$42,MATCH(X16,比對結果!$A$2:$A$42,0))) | I16: ✓ | J16: 透過推動升級優化體驗、創新體系之深度輔導，引導更多糕餅業主動提升產品力、服務力及國內外市場競爭力，以協助臺灣糕餅企業厚實經營基礎、促進糕餅產業升級。 | K16: 100 | L16: 每案政府輔導經費以100萬元（含稅）為上限，企業自籌款不得低於政府輔導經費（含稅）。 | M16: 輔導 / (有輔導款) / (無輔導款) | N16: 每案由1家糕餅企業為主導企業（須為公司組織），結合3家（含）以上企業擔任體系合作單位。 | O16: 限特定對象 | P16: 46139 | Q16: 115/03/02-115/04/27；企業執行期間:自簽約日起至115年11月30日止。 | S16: =IF(ISNUMBER(P16),IF(P16<統計!$B$2,"已截止","受理中"),R16) -> 已截止 | T16: =IF(ISNUMBER(P16),P16-統計!$B$2,"") -> -176 | U16: 僅上傳清單(未獨立核對) | V16: 名稱與上一列相同,依對象區分為主導企業結合3家以上體系合作;政府輔導經費上限100萬(含稅) | W16: https://www.aoc.gov.tw/showPublic/599 | X16: 17
A17: 16 | B17: 上傳清單(經濟部115年方案) | C17: 導入輔導與補助 | D17: 經濟部 | E17: 商業發展署 | F17: 115年度「生活服務業科技創新應用輔導」 | G17: =IF(H17<>"","✓","") | H17: =IF(INDEX(比對結果!$G$2:$G$42,MATCH(X17,比對結果!$A$2:$A$42,0))="","",INDEX(比對結果!$G$2:$G$42,MATCH(X17,比對結果!$A$2:$A$42,0))) | I17: ✓ | J17: 協助生活服務業者運用科技工具發展創新應用服務，以提升經營效率、創造服務價值，強化生活服務業於市場中的長期競爭力。 | K17: 200 | L17: 以200萬元（含稅）為上限 | M17: 輔導 / (有輔導款) / (無輔導款) | N17: (一)依公司法或商業登記法設立之本國公司、商業。；(四) 實際提供生活服務之業者。 | O17: 限特定對象 | P17: 46119 | Q17: 115/03/18-115/04/07；企業執行期間:自審查結果公告日起，至115年11月20日(五)止 | S17: =IF(ISNUMBER(P17),IF(P17<統計!$B$2,"已截止","受理中"),R17) -> 已截止 | T17: =IF(ISNUMBER(P17),P17-統計!$B$2,"") -> -196 | U17: 僅上傳清單(未獨立核對) | V17: 輔導金額上限200萬(含稅) | W17: https://www.aoc.gov.tw/showPublic/608 | X17: 18
A18: 17 | B18: 上傳清單(經濟部115年方案) | C18: 導入輔導與補助 | D18: 經濟部 | E18: 商業發展署 | F18: 115年度「智世代社區短鏈生活圈實證輔導」 | G18: =IF(H18<>"","✓","") | H18: =IF(INDEX(比對結果!$G$2:$G$42,MATCH(X18,比對結果!$A$2:$A$42,0))="","",INDEX(比對結果!$G$2:$G$42,MATCH(X18,比對結果!$A$2:$A$42,0))) | I18: ✓ | J18: 為解決特定實體生活環境目標族群需求與服務取得痛點，生活圈營運者以既有核心服務為基礎，形成生活圈合作團隊，發展科技應用服務於實體場域，整合主題特色多元生活服務，藉以讓目標族群更適時、就近取得多元服務，並為周邊生活服務相關業者創造新商機。 | K18: 300 | L18: 每案以300萬元(含稅)為上限。 | M18: 輔導(有輔導款) / 諮詢/訪視 | N18: (一)依公司法或商業登記法設立之本國公司、商業。；(二)具備生活圈商業經營基礎，包含生活圈實證場域營運基礎、於實證場域具備穩定客源，並提出相關佐證資料如下：；1.已於生活圈實證場域範疇營運至少一年，並提供該場域所在之三級行政區域（鄉、鎮、縣轄市、區）經營具體證明，如營業登記地址、店面租賃合約、場域合作協議、於實證場域提供服務之佐證等。；2.已針對生活圈實證場域特定客群提供服務，並能提供具備穩定客源之佐證，如目標客群服務紀錄、目標客群分析等。；(三)非屬外國營利事業在臺設立之分公司、有限合夥分支機構及陸資企業。；(四)非屬銀行拒絕往來戶。 | O18: 限特定對象 | P18: 46119 | Q18: 115/03/18-115/04/07；企業執行期間:自審查結果公告日起，至115年 11月 20日(五)止。 | S18: =IF(ISNUMBER(P18),IF(P18<統計!$B$2,"已截止","受理中"),R18) -> 已截止 | T18: =IF(ISNUMBER(P18),P18-統計!$B$2,"") -> -196 | U18: 僅上傳清單(未獨立核對) | V18: 每案上限300萬(含稅) | W18: https://www.aoc.gov.tw/showPublic/609 | X18: 19
A19: 18 | B19: 上傳清單(經濟部115年方案) | C19: 非對外公告(委辦/採購) | D19: 經濟部 | E19: 商業發展署 | F19: 營造商業服務業優質發展環境計畫(政策研究委辦案) | G19: =IF(H19<>"","✓","") | H19: =IF(INDEX(比對結果!$G$2:$G$42,MATCH(X19,比對結果!$A$2:$A$42,0))="","",INDEX(比對結果!$G$2:$G$42,MATCH(X19,比對結果!$A$2:$A$42,0))) | I19: ✓ | J19: 本案屬商業服務業政策研究、環境營造與智庫支援工作，附件亦註記為智庫案；採委辦或採購執行，不是一般企業對外申請的補助。 | L19: 依採購預算與契約 | M19: 不適用（委辦／採購） | N19: 具研究、顧問或執行能力之投標單位 | O19: 否 | Q19: 依政府採購／委辦公告；企業執行期間:依採購契約期程 | R19: 非申請制 | S19: =IF(ISNUMBER(P19),IF(P19<統計!$B$2,"已截止","受理中"),R19) -> 非申請制 | T19: =IF(ISNUMBER(P19),P19-統計!$B$2,"") | U19: 僅上傳清單(未獨立核對) | V19: 上傳清單載明為政策研究/智庫委辦案,非對外公開申請 | W19: https://www.aoc.gov.tw/ | X19: 20
A20: 19 | B20: 上傳清單(經濟部115年方案) | C20: 導入輔導與補助 | D20: 經濟部 | E20: 商業發展署 | F20: 115年度「推動商業服務業品牌價值創新成長計畫」輔導 | G20: =IF(H20<>"","✓","") | H20: =IF(INDEX(比對結果!$G$2:$G$42,MATCH(X20,比對結果!$A$2:$A$42,0))="","",INDEX(比對結果!$G$2:$G$42,MATCH(X20,比對結果!$A$2:$A$42,0))) | I20: ✓ | J20: 為鼓勵臺灣商業服務業朝國際品牌邁進，協助商業服務業擴大品牌經營規模、提升品牌價值，加強國際競爭力 | K20: 70 | L20: 一、品牌價值管理輔導：每案上限為35萬元(含稅)；二、海外市場布局輔導：每案上限為40萬元(含稅)；三、品牌海外落地輔導：每案上限為70萬元(含稅) | M20: 輔導(有輔導款) | N20: 一、；申請企業須為經營商業服務業之本國公司、商業或有限合夥登記之企業。本須知所指商業服務業係依據財政部稅籍登記行業代號認定，包含「G批發及零售業」、「H運輸及倉儲業」、「I住宿及餐飲業」、「J出版、影音製作、傳播及資通訊服務業」、「M專業、科學及技術服務業」、「N支援服務業」、「P教育業」、「R藝術、娛樂及休閒服務業」或「S其他服務業」。 | O20: 限特定對象 | P20: 46188 | Q20: 115/05/21-115/06/15；企業執行期間:自評選結果通知日起，至115年10月31日(六)止。 | S20: =IF(ISNUMBER(P20),IF(P20<統計!$B$2,"已截止","受理中"),R20) -> 已截止 | T20: =IF(ISNUMBER(P20),P20-統計!$B$2,"") -> -127 | U20: 僅上傳清單(未獨立核對) | V20: 三類輔導上限:品牌價值管理35萬、海外市場布局40萬、品牌海外落地70萬(上限填最高者) | W20: https://www.aoc.gov.tw/showPublic/677 | X20: 21
A21: 20 | B21: 上傳清單(經濟部115年方案) | C21: 研發補助與投資 | D21: 經濟部 | E21: 商業發展署 | F21: 115年度服務業創新研發計畫(SIIR)申請須知 | G21: =IF(H21<>"","✓","") | H21: =IF(INDEX(比對結果!$G$2:$G$42,MATCH(X21,比對結果!$A$2:$A$42,0))="","",INDEX(比對結果!$G$2:$G$42,MATCH(X21,比對結果!$A$2:$A$42,0))) | I21: ✓ | J21: 鼓勵商業服務業提出創新價值、商業模式清晰且具市場可行性的服務研發計畫。以「智慧化」與「低碳化」為核心，強調智慧科技、跨域整合與永續營運，協助企業推動服務升級與模式創新，加速產業智慧轉型與淨零永續國際競爭力。 | K21: 1200 | L21: 個別創新類：1. 每案補助上限為新臺幣；(以下同 )150萬元。；2. 創新應用領域為「運動 服；務 」 (註2)者， 每案補助上限；為 200萬元 。；合作創新類：1. 每案補助上限為 500萬；元 。；2. 創新應用領域為「運動 服；務 」者， 每案補助上限為；700萬元 。；國際化進階創新類：每案補助上限；1. 個別創新為 500萬元 ；創；新應用領域為「運動 服；務 」者， 每案補助上限為；600萬元 。；2. 合作創新 為 1,000萬元；創新應用領域為「運動；服務 」者， 每案補助上限；為 1,200萬元 。 | M21: 補捐助(補助款) | N21: (一) 依公司法、有限合夥法或商業登記法設立之本國公司、有限合夥或商業；(以下簡稱企業 )。 | O21: 是 | P21: 46052 | Q21: 114/12/17-115/01/30；企業執行期間:115年2月1日起至115年11月30日止 | S21: =IF(ISNUMBER(P21),IF(P21<統計!$B$2,"已截止","受理中"),R21) -> 已截止 | T21: =IF(ISNUMBER(P21),P21-統計!$B$2,"") -> -263 | U21: 僅上傳清單(未獨立核對) | V21: 依類別而異:個別創新150萬(運動服務200萬)、合作創新500萬(700萬)、國際化進階個別500萬(600萬)、合作1,000萬(1,200萬);上限填最高者 | W21: https://www.aoc.gov.tw/showPublic/544 | X21: 22
A22: 21 | B22: 上傳清單(經濟部115年方案) | C22: AI人才培訓 | D22: 經濟部 | E22: 商業發展署 | F22: 115年度服務業AI人才培育計畫 | G22: =IF(H22<>"","✓","") | H22: =IF(INDEX(比對結果!$G$2:$G$42,MATCH(X22,比對結果!$A$2:$A$42,0))="","",INDEX(比對結果!$G$2:$G$42,MATCH(X22,比對結果!$A$2:$A$42,0))) | I22: ✓ | J22: 「服務業AI人才培育計畫」配合國家AI政策及經濟部AI人才培育目標，以產業需求為導向，建構分級分類之AI人才培育體系，針對企業主管、在職從業人員及有志投入服務業者，提供AI基礎知能、實務應用、營運決策及企業導入等多元課程，系統性提升服務業AI應用能力，協助企業運用AI優化營運與服務流程，厚植服務業數位轉型及長期競爭力。 | L22: 不適用 | M22: 訓練/講習/課程 | N22: 商業服務業廠商或有志從事商業服務業人員 | O22: 是 | P22: 46356 | Q22: 115/2/3-115/11/30 | S22: =IF(ISNUMBER(P22),IF(P22<統計!$B$2,"已截止","受理中"),R22) -> 受理中 | T22: =IF(ISNUMBER(P22),P22-統計!$B$2,"") -> 41 | U22: 僅上傳清單(未獨立核對) | V22: 【名稱或簡述提到AI】報名期間2026-02-03至2026-11-30;課程為AI基礎知能、實務應用、營運決策與企業導入;金額欄標示不適用 | X22: 23
A23: 22 | B23: 上傳清單(經濟部115年方案) | C23: 研發補助與投資 | D23: 經濟部 | E23: 產業發展署 | F23: 協助傳統產業技術開發計畫(CITD) | G23: =IF(H23<>"","✓","") | H23: =IF(INDEX(比對結果!$G$2:$G$42,MATCH(X23,比對結果!$A$2:$A$42,0))="","",INDEX(比對結果!$G$2:$G$42,MATCH(X23,比對結果!$A$2:$A$42,0))) | I23: ✓ | J23: 運用政府研發補助資源，鼓勵業者導入新技術，以自行或聯合開發等模式，進行新產品開發，以提升產業研發創新能量，提高產品附加價值。運用計畫輔導、診斷與學習資源，協助業者導入以使用者需求為導向之創新方法，以提高創新產品的市場可行性與研發成功率。 | K23: 1000 | L23: 產品開發最高200萬；研發聯盟每案新臺幣1,000萬元：；1.主導業者：新臺幣500；萬元；2.其餘成員：每家新臺幣；200萬元(註3) | M23: 補捐助（補助款） | N23: 商業服務業 / 技術服務產業；製造業及商業服務業 / 適用製造業及商業服務業；適用產業其他 / 製造業 | O23: 是 | P23: 46062 | Q23: 以經濟部產業發展署或本計畫網站公告為準；即日起至115年2月9日(一)下午17時30分59秒止；企業執行期間:公告受理截止日之次日起至115年11月30日止 | S23: =IF(ISNUMBER(P23),IF(P23<統計!$B$2,"已截止","受理中"),R23) -> 已截止 | T23: =IF(ISNUMBER(P23),P23-統計!$B$2,"") -> -253 | U23: 僅上傳清單(未獨立核對) | V23: 產品開發最高200萬;研發聯盟每案1,000萬(主導業者500萬、其餘成員每家200萬);上限填聯盟額度 | W23: https://keid.nat.gov.tw/citdweb/Web/index.aspx | X23: 24
A24: 23 | B24: 上傳清單(經濟部115年方案) | D24: 經濟部 | E24: 產業發展署 | F24: 推動中小型製造業AI驅動供應鏈智慧製造賦能計畫（智慧機械主題式研發補助） | G24: =IF(H24<>"","✓","") -> ✓ | H24: =IF(INDEX(比對結果!$G$2:$G$42,MATCH(X24,比對結果!$A$2:$A$42,0))="","",INDEX(比對結果!$G$2:$G$42,MATCH(X24,比對結果!$A$2:$A$42,0))) -> 6 | I24: ✓ | V24: 已收錄於「計畫總表」,資料與狀態請見該表對應編號 | X24: 25
A25: 24 | B25: 上傳清單(經濟部115年方案) | C25: 導入輔導與補助 | D25: 經濟部 | E25: 產業發展署 | F25: 數位營運管理服務計畫 | G25: =IF(H25<>"","✓","") | H25: =IF(INDEX(比對結果!$G$2:$G$42,MATCH(X25,比對結果!$A$2:$A$42,0))="","",INDEX(比對結果!$G$2:$G$42,MATCH(X25,比對結果!$A$2:$A$42,0))) | I25: ✓ | J25: 協助企業導入「數位營運管理系統」，推動生產場域無紙化，減少人工作業與資訊落差，同時打造營運數位化，強化從業人員數位化技能，提升交期準確度與整體營運韌性，加速企業轉型再升級。 | K25: 60 | L25: 每案政府經費上限60萬元/每案廠商自籌款10%。 | M25: 輔導 | N25: 金屬機電業 / 金屬產業 | O25: 限特定對象 | P25: 46014 | Q25: 114/10/15-114/12/23；企業執行期間:115/3/1-115/9/15 | S25: =IF(ISNUMBER(P25),IF(P25<統計!$B$2,"已截止","受理中"),R25) -> 已截止 | T25: =IF(ISNUMBER(P25),P25-統計!$B$2,"") -> -301 | U25: 僅上傳清單(未獨立核對) | V25: 每案政府經費上限60萬,廠商自籌10%;限金屬機電業;輔導期2026-03-01至2026-09-15 | W25: https://assist.nat.gov.tw/wSite/ct?xItem=289617&ctNode=150&mp=2 | X25: 26
A26: 25 | B26: 上傳清單(經濟部115年方案) | C26: 導入輔導與補助 | D26: 經濟部 | E26: 產業發展署 | F26: 精實管理蹲點服務計畫 | G26: =IF(H26<>"","✓","") | H26: =IF(INDEX(比對結果!$G$2:$G$42,MATCH(X26,比對結果!$A$2:$A$42,0))="","",INDEX(比對結果!$G$2:$G$42,MATCH(X26,比對結果!$A$2:$A$42,0))) | I26: ✓ | J26: 為協助產業接軌數位轉型趨勢，規劃全方位轉型資源包含（精實管理、數位營運管理），透過政府點線面資源串接與一站式服務，促進數位新動能導入，強化產業競爭力，邁向數位製造發展 | K26: 40 | L26: 每案政府經費上限40萬元/無自籌款。 | M26: 輔導 | N26: 金屬機電業 / 金屬產業 | O26: 限特定對象 | P26: 46014 | Q26: 114/10/15-114/12/23；企業執行期間:115/3/1-115/9/15 | S26: =IF(ISNUMBER(P26),IF(P26<統計!$B$2,"已截止","受理中"),R26) -> 已截止 | T26: =IF(ISNUMBER(P26),P26-統計!$B$2,"") -> -301 | U26: 僅上傳清單(未獨立核對) | V26: 每案政府經費上限40萬,無自籌款;限金屬機電業;輔導期2026-03-01至2026-09-15 | W26: https://assist.nat.gov.tw/wSite/ct?xItem=289617&ctNode=150&mp=2 | X26: 27
A27: 26 | B27: 上傳清單(經濟部115年方案) | C27: 導入輔導與補助 | D27: 經濟部 | E27: 產業發展署 | F27: 民生產業轉型加值計畫 | G27: =IF(H27<>"","✓","") | H27: =IF(INDEX(比對結果!$G$2:$G$42,MATCH(X27,比對結果!$A$2:$A$42,0))="","",INDEX(比對結果!$G$2:$G$42,MATCH(X27,比對結果!$A$2:$A$42,0))) | I27: ✓ | J27: 本計畫以「創新加值」為主軸，藉由精實管理與數位導入，協助袋包、毛巾、烘焙食品等民生相關產業達到快速開發、彈性生產之目標。 | L27: 每案廠商自籌款占個案計畫總經費20%以上。 | M27: 輔導 | N27: 民生化工業 / 紡織產業, 食品產業；中小企業 / 限中小企業 | O27: 限特定對象 | P27: 46203 | Q27: 115/1/1-115/6/30；企業執行期間:至簽約起至115/11/30 | S27: =IF(ISNUMBER(P27),IF(P27<統計!$B$2,"已截止","受理中"),R27) -> 已截止 | T27: =IF(ISNUMBER(P27),P27-統計!$B$2,"") -> -112 | U27: 僅上傳清單(未獨立核對) | V27: 廠商自籌款須占總經費20%以上;限民生化工業中小企業 | W27: https://assist.nat.gov.tw/wSite/ct?xItem=289529&ctNode=150&mp=2 | X27: 28
A28: 27 | B28: 上傳清單(經濟部115年方案) | C28: 研發補助與投資 | D28: 經濟部 | E28: 產業發展署 | F28: 中小製造業接班傳承AI應用數位轉型(主題式研發補助) | G28: =IF(H28<>"","✓","") | H28: =IF(INDEX(比對結果!$G$2:$G$42,MATCH(X28,比對結果!$A$2:$A$42,0))="","",INDEX(比對結果!$G$2:$G$42,MATCH(X28,比對結果!$A$2:$A$42,0))) | I28: ✓ | J28: 為協助中小型製造業者運用數位科技與人工智慧達成數位轉型目標，創造新商業模式，提供補助資源，鼓勵企業接班人透過創新思考模式，主導或協助公司進行數位轉型，重塑企業DNA建立新思維，並促使企業完成接班。 | K28: 800 | L28: 轉型實踐案每案政府補助經費以新臺幣800萬元為上限，政府補助經費占總計畫經費以50%為上限。 | M28: 補助 | N28: 中小型製造業 | O28: 限特定對象 | P28: 46139 | Q28: 受理申請開始時間自公告日起至115年4月27日止。；企業執行期間:以1年為上限，並以收件截止日為計畫起始日。 | S28: =IF(ISNUMBER(P28),IF(P28<統計!$B$2,"已截止","受理中"),R28) -> 已截止 | T28: =IF(ISNUMBER(P28),P28-統計!$B$2,"") -> -176 | U28: 僅上傳清單(未獨立核對) | V28: 【名稱或簡述提到AI】轉型實踐案每案政府補助上限800萬,不超過總經費50%;執行期以1年為上限 | W28: https://assist.nat.gov.tw/wSite/ct?xItem=289605&ctNode=150&mp=2 | X28: 29
A29: 28 | B29: 上傳清單(經濟部115年方案) | C29: 導入輔導與補助 | D29: 經濟部 | E29: 產業發展署 | F29: 協助中小型製造業數位轉型躍升計畫(委辦執行部分) | G29: =IF(H29<>"","✓","") | H29: =IF(INDEX(比對結果!$G$2:$G$42,MATCH(X29,比對結果!$A$2:$A$42,0))="","",INDEX(比對結果!$G$2:$G$42,MATCH(X29,比對結果!$A$2:$A$42,0))) | I29: ✓ | J29: 透過共通輔導手法，推動中小型製造業數位轉型，協助提出新模式、新產品與新服務，研擬數位轉型輔導指南；盤點產業需求；規劃適性化解決方案；整合跨領域專家輔導團隊，協助數位轉型解決方案導入，達成增加營收、擴大海外市場與帶動薪資成長之目標。 | K29: 75 | L29: 每案政府委辦經費75萬元、廠商自籌款15萬元。 | M29: 輔導（有輔導款） | N29: 中小型製造業 | O29: 限特定對象 | Q29: 受理申請開始時間自5月中旬起至6月中旬止。；企業執行期間:經當年度遴選後，輔導約5個月。 | R29: 未確認 | S29: =IF(ISNUMBER(P29),IF(P29<統計!$B$2,"已截止","受理中"),R29) -> 未確認 | T29: =IF(ISNUMBER(P29),P29-統計!$B$2,"") | U29: 僅上傳清單(未獨立核對) | V29: 每案政府委辦經費75萬、廠商自籌15萬;受理期間只寫「5月中旬至6月中旬」,未載年份與日期,依115年度推斷應已結束,請確認 | W29: https://www.ida.gov.tw/ctlr?PRO=project.rwdProjectView&id=2814 | X29: 30
A30: 29 | B30: 上傳清單(經濟部115年方案) | C30: 導入輔導與補助 | D30: 經濟部 | E30: 產業發展署 | F30: 數據驅動製造業研發創新計畫 | G30: =IF(H30<>"","✓","") | H30: =IF(INDEX(比對結果!$G$2:$G$42,MATCH(X30,比對結果!$A$2:$A$42,0))="","",INDEX(比對結果!$G$2:$G$42,MATCH(X30,比對結果!$A$2:$A$42,0))) | I30: ✓ | J30: 為因應數位環境加速發展，以子產業別為對象以數位普及、賦能轉型及推廣擴散等策略作法，推動數位轉型的構想普及，透過開源工具體驗運用建構產業現有人力的數位基礎能力，強化產業轉型基礎，提升作業效率及產能，達到創造新價值的數位轉型目標。 | K30: 50 | L30: 1.產品開發POC(Proof of Concept)導入驗證每案新臺幣25萬元(含稅)：含政府款15萬元，廠商自籌款10萬元。；2.產品試銷POB(Proof of Business)導入驗證(註)；每案新臺幣75萬元(含稅)：含政府款50萬元，廠商自籌款25萬元。 | M30: 輔導（有輔導款） | N30: 中小型製造業 | O30: 限特定對象 | Q30: 自公告日起至年度驗證家數額度滿額為止，即停止受理。；企業執行期間:自公告日起至；115年11月30日止。 | R30: 常態開放 | S30: =IF(ISNUMBER(P30),IF(P30<統計!$B$2,"已截止","受理中"),R30) -> 常態開放 | T30: =IF(ISNUMBER(P30),P30-統計!$B$2,"") | U30: 僅上傳清單(未獨立核對) | V30: 受理至年度驗證家數額滿為止;POC驗證每案25萬(政府15萬)、POB驗證每案75萬(政府50萬);執行至2026-11-30 | W30: https://assist.nat.gov.tw/wSite/ct?xItem=289634&ctNode=150&mp=2 | X30: 31
A31: 30 | B31: 上傳清單(經濟部115年方案) | C31: 導入輔導與補助 | D31: 經濟部 | E31: 產業發展署 | F31: 食品製造業數位轉型應用加值計畫 | G31: =IF(H31<>"","✓","") | H31: =IF(INDEX(比對結果!$G$2:$G$42,MATCH(X31,比對結果!$A$2:$A$42,0))="","",INDEX(比對結果!$G$2:$G$42,MATCH(X31,比對結果!$A$2:$A$42,0))) | I31: ✓ | J31: 為因應數位環境加速發展，以子產業別為對象以數位普及、賦能轉型及推廣擴散等策略作法，推動數位轉型的構想普及，透過開源工具體驗運用建構產業現有人力的數位基礎能力，強化產業轉型基礎，提升作業效率及產能，達到創造新價值的數位轉型目標。 | K31: 75 | L31: 每案政府委辦經費75萬元，每案廠商自籌款37.5萬元。 | M31: 輔導（有輔導款） | N31: 中小製造業 | O31: 限特定對象 | P31: 46096 | Q31: 自公告日起至115年3月15日止。；企業執行期間:自公告日起至；9月30日截止。 | S31: =IF(ISNUMBER(P31),IF(P31<統計!$B$2,"已截止","受理中"),R31) -> 已截止 | T31: =IF(ISNUMBER(P31),P31-統計!$B$2,"") -> -219 | U31: 僅上傳清單(未獨立核對) | V31: 每案政府委辦經費75萬、廠商自籌37.5萬;由輔導團隊洽詢意願 | W31: https://assist.nat.gov.tw/wSite/ct?xItem=289512&ctNode=150&mp=2 | X31: 32
A32: 31 | B32: 上傳清單(經濟部115年方案) | C32: 導入輔導與補助 | D32: 經濟部 | E32: 產業發展署 | F32: 塑橡膠製造業數位轉型應用加值計畫 | G32: =IF(H32<>"","✓","") | H32: =IF(INDEX(比對結果!$G$2:$G$42,MATCH(X32,比對結果!$A$2:$A$42,0))="","",INDEX(比對結果!$G$2:$G$42,MATCH(X32,比對結果!$A$2:$A$42,0))) | I32: ✓ | J32: 輔導塑橡膠製品業者產業數位升級，強化研發與製造量能，並依產業需求，運用相關數位科技，促使塑橡膠業者提升數位化層級，擴大數位轉型比例為目標，以擴大整體轉型效益。 | L32: 政府款：自籌款＝2:1；(輔導款額度用罄為止) | M32: 輔導（有輔導款） | N32: 民生化工業 / 化學材料產業, 應用材料產業；中小企業 / 限中小企業 | O32: 限特定對象 | Q32: 自115年1月1日起，或本年度產業發展署輔導款額度用罄為止。；企業執行期間:自公告日起至115年11月30日止。 | R32: 常態開放 | S32: =IF(ISNUMBER(P32),IF(P32<統計!$B$2,"已截止","受理中"),R32) -> 常態開放 | T32: =IF(ISNUMBER(P32),P32-統計!$B$2,"") | U32: 僅上傳清單(未獨立核對) | V32: 政府款與自籌款比例2:1;自2026-01-01起受理,輔導款額度用罄為止;執行至2026-11-30 | X32: 33
A33: 32 | B33: 上傳清單(經濟部115年方案) | C33: 導入輔導與補助 | D33: 經濟部 | E33: 產業發展署 | F33: 戶外休閒紡織製造業數位轉型應用加值計畫 | G33: =IF(H33<>"","✓","") | H33: =IF(INDEX(比對結果!$G$2:$G$42,MATCH(X33,比對結果!$A$2:$A$42,0))="","",INDEX(比對結果!$G$2:$G$42,MATCH(X33,比對結果!$A$2:$A$42,0))) | I33: ✓ | J33: 本計畫串聯公協會辦理到廠訪視，擴大中小製造業及次產業參與政府輔導資源。以接單廠為核心，帶動二階供應鏈與在地系統廠，導入數位生產、供應鏈與智慧排程管理，結合機聯、可視化與 AI 技術，提升產線效率與交期準確度，建立產業轉型典範，擴大數位轉型滲透。 | K33: 250 | L33: 每案政府委辦經費上限250萬元，每案廠商自籌款107.5萬元/比例30%。 | M33: 輔導（有輔導款） | N33: 民生化工業 / 紡織產業；中小企業 / 限中小企業；製造業及商業服務業 / 適用製造業及商業服務業 | O33: 限特定對象 | Q33: 自115年1月1日起，或本年度產業發展署輔導款額度用罄為止。；企業執行期間:自說明會日起至；115年6月30日止。 | R33: 未確認 | S33: =IF(ISNUMBER(P33),IF(P33<統計!$B$2,"已截止","受理中"),R33) -> 未確認 | T33: =IF(ISNUMBER(P33),P33-統計!$B$2,"") | U33: 僅上傳清單(未獨立核對) | V33: 【名稱或簡述提到AI】每案政府委辦經費上限250萬、自籌107.5萬(30%);受理期間欄寫額度用罄為止,但企業執行期間欄寫至2026-06-30,兩欄可能互相對調,請確認 | W33: https://assist.nat.gov.tw/wSite/ct?xItem=289511&ctNode=150&mp=2 | X33: 34
A34: 33 | B34: 上傳清單(經濟部115年方案) | C34: 導入輔導與補助 | D34: 經濟部 | E34: 產業發展署 | F34: 化粧品製造業數位轉型應用加值計畫 | G34: =IF(H34<>"","✓","") | H34: =IF(INDEX(比對結果!$G$2:$G$42,MATCH(X34,比對結果!$A$2:$A$42,0))="","",INDEX(比對結果!$G$2:$G$42,MATCH(X34,比對結果!$A$2:$A$42,0))) | I34: ✓ | J34: 本計畫擬盤點國內化粧品產業現況，依據業者規模及積極度，訂定訪視順序並提供客製化解決方案。對於尚未運用數位工具企業，協助導入數位化管理系統；而具備數位轉型潛力業者，則強化生產與營運階段之數位優化，形塑數位轉型典範案例擴散至整體產業。 | L34: 每案政府經費/廠商自籌款比例上限 1:1。 | M34: 輔導（有輔導款） | N34: 化粧品製造業 | O34: 限特定對象 | Q34: 自115年1月1日起，或本年度產業發展署輔導款額度用罄為止。；企業執行期間:經當年度遴選通過後，輔導期間至115年11月30日止。 | R34: 常態開放 | S34: =IF(ISNUMBER(P34),IF(P34<統計!$B$2,"已截止","受理中"),R34) -> 常態開放 | T34: =IF(ISNUMBER(P34),P34-統計!$B$2,"") | U34: 僅上傳清單(未獨立核對) | V34: 政府經費與廠商自籌比例上限1:1;自2026-01-01起受理,輔導款額度用罄為止;輔導期至2026-11-30 | W34: https://assist.nat.gov.tw/wSite/ct?xItem=289564&ctNode=150&mp=2 | X34: 35
A35: 34 | B35: 上傳清單(經濟部115年方案) | C35: 研發補助與投資 | D35: 經濟部 | E35: 中小及新創企業署 | F35: 扶植新創驅動企業創新轉型計畫（推動中小及新創企業創育機構發展計畫） | G35: =IF(H35<>"","✓","") | H35: =IF(INDEX(比對結果!$G$2:$G$42,MATCH(X35,比對結果!$A$2:$A$42,0))="","",INDEX(比對結果!$G$2:$G$42,MATCH(X35,比對結果!$A$2:$A$42,0))) | I35: ✓ | J35: 強化創育機構服務量能與新創支援網絡，協助新創團隊取得培育、資源媒合與成長服務；是否對外受理及資源內容，應依年度公告或個別徵案判定。 | L35: 依徵案或輔導方案 | M35: 補捐助（補助款） | N35: 創育機構、新創支援單位及受輔導新創 | O35: 限特定對象 | Q35: 依年度公告 | R35: 未確認 | S35: =IF(ISNUMBER(P35),IF(P35<統計!$B$2,"已截止","受理中"),R35) -> 未確認 | T35: =IF(ISNUMBER(P35),P35-統計!$B$2,"") | U35: 僅上傳清單(未獨立核對) | V35: 上傳清單的受理期間與金額均寫「依年度公告」 | W35: https://startup.sme.gov.tw/incubator/news/68d2431cde1b4a5e8b10f76b | X35: 36
A36: 35 | B36: 上傳清單(經濟部115年方案) | C36: 研發補助與投資 | D36: 經濟部 | E36: 中小及新創企業署 | F36: 推動跨域研發引領中小企業升級轉型計畫（SBIR跨域研發，115案） | G36: =IF(H36<>"","✓","") | H36: =IF(INDEX(比對結果!$G$2:$G$42,MATCH(X36,比對結果!$A$2:$A$42,0))="","",INDEX(比對結果!$G$2:$G$42,MATCH(X36,比對結果!$A$2:$A$42,0))) | I36: ✓ | J36: 鼓勵中小企業與新創企業組成聯盟，針對AI智慧應用、無人載具或淨零等主軸共同研發，強化跨域創新、技術商轉與市場拓展能力。 | K36: 700 | L36: 每案最高700萬；自籌款至少50% | M36: 補捐助（補助款） | N36: 至少2家中小企業組成聯盟，且其中1家須為新創 | O36: 限特定對象 | P36: 46000 | Q36: 公告日起至114/12/09 17:30（115案）；企業執行期間:公告核定當月1日起至115年10月15日止 | S36: =IF(ISNUMBER(P36),IF(P36<統計!$B$2,"已截止","受理中"),R36) -> 已截止 | T36: =IF(ISNUMBER(P36),P36-統計!$B$2,"") -> -315 | U36: 僅上傳清單(未獨立核對) | V36: 【名稱或簡述提到AI】每案最高700萬,自籌款至少50%;須至少2家中小企業組成聯盟,其中1家為新創 | W36: https://sbir.org.tw/news/main_content?id=12253&page=5 | X36: 37
A37: 36 | B37: 上傳清單(經濟部115年方案) | C37: 導入輔導與補助 | D37: 經濟部 | E37: 中小及新創企業署 | F37: 115年度小微企業區域數位加值與創新體驗計畫（城鄉聯盟） | G37: =IF(H37<>"","✓","") | H37: =IF(INDEX(比對結果!$G$2:$G$42,MATCH(X37,比對結果!$A$2:$A$42,0))="","",INDEX(比對結果!$G$2:$G$42,MATCH(X37,比對結果!$A$2:$A$42,0))) | I37: ✓ | J37: 以城鄉聯盟整合地方店家與產業動能，透過數位加值、創新體驗、通路媒合與組織化輔導，建立可商轉且具永續性的區域特色產業模式。 | L37: 輔導案；依115須知 | M37: 輔導（有輔導款） | N37: 在地企業、法人或公協會代表城鄉聯盟提案 | O37: 限特定對象 | P37: 46127 | Q37: 公告日起至115/04/15；企業執行期間:依核定輔導期程（受理至115年4月15日止） | S37: =IF(ISNUMBER(P37),IF(P37<統計!$B$2,"已截止","受理中"),R37) -> 已截止 | T37: =IF(ISNUMBER(P37),P37-統計!$B$2,"") -> -188 | U37: 僅上傳清單(未獨立核對) | V37: 輔導案,金額依115年度須知;由在地企業、法人或公協會代表城鄉聯盟提案 | W37: https://www.sme.gov.tw/article-tw-2275-14428 | X37: 38
A38: 37 | B38: 上傳清單(經濟部115年方案) | C38: 非對外公告(委辦/採購) | D38: 經濟部 | E38: 中小及新創企業署 | F38: 中小企業數據驅動政策校準與輔導策略強化計畫(政策研究委辦案) | G38: =IF(H38<>"","✓","") | H38: =IF(INDEX(比對結果!$G$2:$G$42,MATCH(X38,比對結果!$A$2:$A$42,0))="","",INDEX(比對結果!$G$2:$G$42,MATCH(X38,比對結果!$A$2:$A$42,0))) | I38: ✓ | J38: 本案為中小微企業科技應用、政策校準與包容成長的政策研究或執行支援工作，附件註記為智庫案；屬委辦採購，而不是企業直接申請的補助。 | L38: 依採購預算與契約 | M38: 不適用（委辦／採購） | N38: 具研究、顧問或執行能力之投標單位 | O38: 否 | Q38: 依政府採購／委辦公告；企業執行期間:依採購契約期程 | R38: 非申請制 | S38: =IF(ISNUMBER(P38),IF(P38<統計!$B$2,"已截止","受理中"),R38) -> 非申請制 | T38: =IF(ISNUMBER(P38),P38-統計!$B$2,"") | U38: 僅上傳清單(未獨立核對) | V38: 上傳清單載明為政策研究/智庫委辦案,非對外公開申請 | W38: https://www.sme.gov.tw/ | X38: 39
A39: 38 | B39: 上傳清單(經濟部115年方案) | C39: 導入輔導與補助 | D39: 經濟部 | E39: 中小及新創企業署 | F39: 中小企業數據創新加值計畫（推動中小企業創新經濟開拓市場計畫） | G39: =IF(H39<>"","✓","") | H39: =IF(INDEX(比對結果!$G$2:$G$42,MATCH(X39,比對結果!$A$2:$A$42,0))="","",INDEX(比對結果!$G$2:$G$42,MATCH(X39,比對結果!$A$2:$A$42,0))) | I39: ✓ | J39: 透過諮詢診斷、人才培育與群聚輔導，協助生活消費相關中小企業以數據應用、供應鏈整合與創新商模開拓市場及提升商機。 | L39: 輔導案；依115須知 | M39: 輔導（有輔導款） | N39: 符合中小企業認定標準且已公司或商業登記之業者 | O39: 是 | P39: 46134 | Q39: 公告日起至115/04/22 17:00；企業執行期間:依核定輔導期程（受理至115年4月22日17:00止） | S39: =IF(ISNUMBER(P39),IF(P39<統計!$B$2,"已截止","受理中"),R39) -> 已截止 | T39: =IF(ISNUMBER(P39),P39-統計!$B$2,"") -> -181 | U39: 僅上傳清單(未獨立核對) | V39: 輔導案,金額依115年度須知;截止2026-04-22 17:00 | W39: https://www.sme.gov.tw/article-tw-2814-14140 | X39: 40
A40: 39 | B40: 上傳清單(經濟部115年方案) | C40: 導入輔導與補助 | D40: 經濟部 | E40: 中小及新創企業署 | F40: 創業資源整備服務計畫（115年度臺灣創業服務發展計畫） | G40: =IF(H40<>"","✓","") | H40: =IF(INDEX(比對結果!$G$2:$G$42,MATCH(X40,比對結果!$A$2:$A$42,0))="","",INDEX(比對結果!$G$2:$G$42,MATCH(X40,比對結果!$A$2:$A$42,0))) | I40: ✓ | J40: 整備創業服務資源、強化新創支持網絡與創業環境，可能透過活動、服務或委辦項目提供資源；是否開放申請與對象需依各年度子方案判定。 | L40: 依子方案；未見固定金額 | M40: 輔導（無輔導款）／諮詢訪視 | N40: 新創企業、創業團隊及服務機構 | O40: 限特定對象 | Q40: 依年度活動、服務或委辦公告 | R40: 未確認 | S40: =IF(ISNUMBER(P40),IF(P40<統計!$B$2,"已截止","受理中"),R40) -> 未確認 | T40: =IF(ISNUMBER(P40),P40-統計!$B$2,"") | U40: 僅上傳清單(未獨立核對) | V40: 依子方案規定,無固定金額與期限 | W40: https://assist.nat.gov.tw/wSite/ct?xItem=289505&ctNode=150&mp=2 | X40: 41
...

Sheet 比對結果
A1: 上傳清單列號 | B1: 機關 | C1: 綱要計畫名稱 | D1: 政策資源名稱(對外公告) | E1: 上傳檔「是否納入」 | F1: 名稱或簡述提到AI | G1: 對應完整版編號 | H1: 完整版計畫名稱 | I1: 比對說明
A2: 2 | B2: 數位產業署 | C2: 資服業轉型雲服務暨推廣計畫 | D2: 115年度AI創新服務研發補助計畫 | E2: Y | F2: 是 | G2: 14 | H2: =IFERROR(INDEX(計畫總表!$F$2:$F$27,MATCH(G2,計畫總表!$A$2:$A$27,0)),"") -> AI創新服務研發補助計畫(115年) | I2: 同一計畫:數位產業署AI創新服務研發補助計畫;名稱相同,申請至7/24、上限500萬/2,000萬一致
A3: 4 | B3: 產業技術司 | C3: 新創前瞻技術淬鍊計畫 | D3: A+企業創新研發淬鍊計畫－前瞻技術創業投資計畫(A+STEP) | E3: Y | H3: =IFERROR(INDEX(計畫總表!$F$2:$F$27,MATCH(G3,計畫總表!$A$2:$A$27,0)),"") | I3: 完整版未收錄
A4: 5 | B4: 產業技術司 | C4: 新創前瞻技術淬鍊計畫 | D4: 2026年國際鏈結與商業概念驗證專案 | E4: Y | H4: =IFERROR(INDEX(計畫總表!$F$2:$F$27,MATCH(G4,計畫總表!$A$2:$A$27,0)),"") | I4: 完整版未收錄
A5: 6 | B5: 產業技術司 | C5: 新創前瞻技術淬鍊計畫 | D5: 2026年國際鏈結與商業概念驗證專案（TREE Landing Program）第二次擴大徵案 | E5: Y | H5: =IFERROR(INDEX(計畫總表!$F$2:$F$27,MATCH(G5,計畫總表!$A$2:$A$27,0)),"") | I5: 完整版未收錄
A6: 7 | B6: 國際貿易署 | C6: 中小企業整體競爭力提升方案-運用數位新貿易模式計畫 | D6: 無（本案屬平台建置委辦／採購案，非對外公告之政策資源） | E6: N | H6: =IFERROR(INDEX(計畫總表!$F$2:$F$27,MATCH(G6,計畫總表!$A$2:$A$27,0)),"") | I6: 完整版未收錄
A7: 8 | B7: 國際貿易署 | C7: 中小企業整體競爭力提升方案-運用數位新貿易模式計畫 | D7: 運用數位新貿易模式計畫 | E7: Y | F7: 是 | H7: =IFERROR(INDEX(計畫總表!$F$2:$F$27,MATCH(G7,計畫總表!$A$2:$A$27,0)),"") | I7: 完整版未收錄
A8: 9 | B8: 商業發展署 | C8: 商業服務業數據驅動價值創造計畫 | D8: 115年度「商業服務業數據驅動價值創造計畫」輔導案 | E8: Y | F8: 是 | H8: =IFERROR(INDEX(計畫總表!$F$2:$F$27,MATCH(G8,計畫總表!$A$2:$A$27,0)),"") | I8: 完整版未收錄
A9: 10 | B9: 商業發展署 | C9: 商業服務業創新科技加值發展計畫 | D9: 街區品牌特色發展計畫 | E9: Y | H9: =IFERROR(INDEX(計畫總表!$F$2:$F$27,MATCH(G9,計畫總表!$A$2:$A$27,0)),"") | I9: 完整版未收錄
A10: 11 | B10: 商業發展署 | C10: 商業服務業創新科技加值發展計畫 | D10: 115年度「老店創生輔導」 | E10: Y | H10: =IFERROR(INDEX(計畫總表!$F$2:$F$27,MATCH(G10,計畫總表!$A$2:$A$27,0)),"") | I10: 完整版未收錄
A11: 12 | B11: 商業發展署 | C11: 商業服務業創新科技加值發展計畫 | D11: 115年度「推動餐飲服務業優質成長暨國際推廣計畫」產品開發試銷輔導 | E11: Y | H11: =IFERROR(INDEX(計畫總表!$F$2:$F$27,MATCH(G11,計畫總表!$A$2:$A$27,0)),"") | I11: 完整版未收錄
A12: 13 | B12: 商業發展署 | C12: 商業服務業創新科技加值發展計畫 | D12: 115年度「推動餐飲服務業優質成長暨國際推廣計畫」通路拓展輔導 | E12: Y | H12: =IFERROR(INDEX(計畫總表!$F$2:$F$27,MATCH(G12,計畫總表!$A$2:$A$27,0)),"") | I12: 完整版未收錄
A13: 14 | B13: 商業發展署 | C13: 商業服務業創新科技加值發展計畫 | D13: 115年度「推動餐飲服務業優質成長暨國際推廣計畫」餐飲體系輔導 | E13: Y | H13: =IFERROR(INDEX(計畫總表!$F$2:$F$27,MATCH(G13,計畫總表!$A$2:$A$27,0)),"") | I13: 完整版未收錄
A14: 15 | B14: 商業發展署 | C14: 商業服務業創新科技加值發展計畫 | D14: 115年度「推動餐飲服務業優質成長暨國際推廣計畫」餐廳雙語服務提升輔導 | E14: Y | H14: =IFERROR(INDEX(計畫總表!$F$2:$F$27,MATCH(G14,計畫總表!$A$2:$A$27,0)),"") | I14: 完整版未收錄
A15: 16 | B15: 商業發展署 | C15: 商業服務業創新科技加值發展計畫 | D15: 115年度「糕餅業創新永續發展計畫」糕餅業深度輔導 | E15: Y | H15: =IFERROR(INDEX(計畫總表!$F$2:$F$27,MATCH(G15,計畫總表!$A$2:$A$27,0)),"") | I15: 完整版未收錄
A16: 17 | B16: 商業發展署 | C16: 商業服務業創新科技加值發展計畫 | D16: 115年度「糕餅業創新永續發展計畫」糕餅業深度輔導 | E16: Y | H16: =IFERROR(INDEX(計畫總表!$F$2:$F$27,MATCH(G16,計畫總表!$A$2:$A$27,0)),"") | I16: 完整版未收錄
A17: 18 | B17: 商業發展署 | C17: 商業服務業創新科技加值發展計畫 | D17: 115年度「生活服務業科技創新應用輔導」 | E17: Y | H17: =IFERROR(INDEX(計畫總表!$F$2:$F$27,MATCH(G17,計畫總表!$A$2:$A$27,0)),"") | I17: 完整版未收錄
A18: 19 | B18: 商業發展署 | C18: 商業服務業創新科技加值發展計畫 | D18: 115年度「智世代社區短鏈生活圈實證輔導」 | E18: Y | H18: =IFERROR(INDEX(計畫總表!$F$2:$F$27,MATCH(G18,計畫總表!$A$2:$A$27,0)),"") | I18: 完整版未收錄
A19: 20 | B19: 商業發展署 | C19: 商業服務業創新科技加值發展計畫 | D19: 無（本案屬政策研究／智庫委辦案，非對外公開申請） | E19: N | H19: =IFERROR(INDEX(計畫總表!$F$2:$F$27,MATCH(G19,計畫總表!$A$2:$A$27,0)),"") | I19: 完整版未收錄
A20: 21 | B20: 商業發展署 | C20: 商業服務業創新科技加值發展計畫 | D20: 115年度「推動商業服務業品牌價值創新成長計畫」輔導 | E20: Y | H20: =IFERROR(INDEX(計畫總表!$F$2:$F$27,MATCH(G20,計畫總表!$A$2:$A$27,0)),"") | I20: 完整版未收錄
A21: 22 | B21: 商業發展署 | C21: 商業服務業創新科技加值發展計畫 | D21: 115年度服務業創新研發計畫(SIIR)申請須知 | E21: Y | H21: =IFERROR(INDEX(計畫總表!$F$2:$F$27,MATCH(G21,計畫總表!$A$2:$A$27,0)),"") | I21: 完整版未收錄
A22: 23 | B22: 商業發展署 | C22: 商業服務業創新科技加值發展計畫 | D22: 115年度服務業AI人才培育計畫 | E22: Y | F22: 是 | H22: =IFERROR(INDEX(計畫總表!$F$2:$F$27,MATCH(G22,計畫總表!$A$2:$A$27,0)),"") | I22: 完整版未收錄
A23: 24 | B23: 產業發展署 | C23: 促進中小型製造業轉型加值計畫 | D23: 協助傳統產業技術開發計畫(CITD) | E23: Y | H23: =IFERROR(INDEX(計畫總表!$F$2:$F$27,MATCH(G23,計畫總表!$A$2:$A$27,0)),"") | I23: 完整版未收錄
A24: 25 | B24: 產業發展署 | C24: 促進中小型製造業轉型加值計畫 | D24: 推動中小型製造業AI驅動供應鏈智慧製造賦能計畫（智慧機械主題式研發補助） | E24: Y | F24: 是 | G24: 6 | H24: =IFERROR(INDEX(計畫總表!$F$2:$F$27,MATCH(G24,計畫總表!$A$2:$A$27,0)),"") -> 智慧機械-產業聚落供應鏈數位串流暨AI應用 | I24: 同一計畫:智慧機械主題式研發補助(供應鏈智慧製造),完整版名稱為「智慧機械-產業聚落供應鏈數位串流暨AI應用」;1,500萬、5/4截止一致
A25: 26 | B25: 產業發展署 | C25: 促進中小型製造業轉型加值計畫 | D25: 數位營運管理服務計畫 | E25: Y | H25: =IFERROR(INDEX(計畫總表!$F$2:$F$27,MATCH(G25,計畫總表!$A$2:$A$27,0)),"") | I25: 完整版未收錄
A26: 27 | B26: 產業發展署 | C26: 促進中小型製造業轉型加值計畫 | D26: 精實管理蹲點服務計畫 | E26: Y | H26: =IFERROR(INDEX(計畫總表!$F$2:$F$27,MATCH(G26,計畫總表!$A$2:$A$27,0)),"") | I26: 完整版未收錄
A27: 28 | B27: 產業發展署 | C27: 促進中小型製造業轉型加值計畫 | D27: 民生產業轉型加值計畫 | E27: Y | H27: =IFERROR(INDEX(計畫總表!$F$2:$F$27,MATCH(G27,計畫總表!$A$2:$A$27,0)),"") | I27: 完整版未收錄
A28: 29 | B28: 產業發展署 | C28: 製造業數位轉型應用加值計畫 | D28: 中小製造業接班傳承AI應用數位轉型(主題式研發補助) | E28: Y | F28: 是 | H28: =IFERROR(INDEX(計畫總表!$F$2:$F$27,MATCH(G28,計畫總表!$A$2:$A$27,0)),"") | I28: 完整版未收錄
A29: 30 | B29: 產業發展署 | C29: 製造業數位轉型應用加值計畫 | D29: 協助中小型製造業數位轉型躍升計畫(委辦執行部分) | E29: Y | H29: =IFERROR(INDEX(計畫總表!$F$2:$F$27,MATCH(G29,計畫總表!$A$2:$A$27,0)),"") | I29: 完整版未收錄
A30: 31 | B30: 產業發展署 | C30: 製造業數位轉型應用加值計畫 | D30: 數據驅動製造業研發創新計畫 | E30: Y | H30: =IFERROR(INDEX(計畫總表!$F$2:$F$27,MATCH(G30,計畫總表!$A$2:$A$27,0)),"") | I30: 完整版未收錄
A31: 32 | B31: 產業發展署 | C31: 製造業數位轉型應用加值計畫 | D31: 食品製造業數位轉型應用加值計畫 | E31: Y | H31: =IFERROR(INDEX(計畫總表!$F$2:$F$27,MATCH(G31,計畫總表!$A$2:$A$27,0)),"") | I31: 完整版未收錄
A32: 33 | B32: 產業發展署 | C32: 製造業數位轉型應用加值計畫 | D32: 塑橡膠製造業數位轉型應用加值計畫 | E32: Y | H32: =IFERROR(INDEX(計畫總表!$F$2:$F$27,MATCH(G32,計畫總表!$A$2:$A$27,0)),"") | I32: 完整版未收錄
A33: 34 | B33: 產業發展署 | C33: 製造業數位轉型應用加值計畫 | D33: 戶外休閒紡織製造業數位轉型應用加值計畫 | E33: Y | F33: 是 | H33: =IFERROR(INDEX(計畫總表!$F$2:$F$27,MATCH(G33,計畫總表!$A$2:$A$27,0)),"") | I33: 完整版未收錄
A34: 35 | B34: 產業發展署 | C34: 製造業數位轉型應用加值計畫 | D34: 化粧品製造業數位轉型應用加值計畫 | E34: Y | H34: =IFERROR(INDEX(計畫總表!$F$2:$F$27,MATCH(G34,計畫總表!$A$2:$A$27,0)),"") | I34: 完整版未收錄
A35: 36 | B35: 中小及新創企業署 | C35: 加速共創研發推動計畫 | D35: 扶植新創驅動企業創新轉型計畫（推動中小及新創企業創育機構發展計畫） | E35: Y | H35: =IFERROR(INDEX(計畫總表!$F$2:$F$27,MATCH(G35,計畫總表!$A$2:$A$27,0)),"") | I35: 完整版未收錄
A36: 37 | B36: 中小及新創企業署 | C36: 加速共創研發推動計畫 | D36: 推動跨域研發引領中小企業升級轉型計畫（SBIR跨域研發，115案） | E36: Y | F36: 是 | H36: =IFERROR(INDEX(計畫總表!$F$2:$F$27,MATCH(G36,計畫總表!$A$2:$A$27,0)),"") | I36: 完整版未收錄
A37: 38 | B37: 中小及新創企業署 | C37: 加速共創研發推動計畫 | D37: 115年度小微企業區域數位加值與創新體驗計畫（城鄉聯盟） | E37: Y | H37: =IFERROR(INDEX(計畫總表!$F$2:$F$27,MATCH(G37,計畫總表!$A$2:$A$27,0)),"") | I37: 完整版未收錄
A38: 39 | B38: 中小及新創企業署 | C38: 科技應用驅動中小微企業包容成長計畫 | D38: 無（本案屬政策研究／智庫委辦案，非對外公開申請） | E38: N | H38: =IFERROR(INDEX(計畫總表!$F$2:$F$27,MATCH(G38,計畫總表!$A$2:$A$27,0)),"") | I38: 完整版未收錄
A39: 40 | B39: 中小及新創企業署 | C39: 科技應用驅動中小微企業包容成長計畫 | D39: 中小企業數據創新加值計畫（推動中小企業創新經濟開拓市場計畫） | E39: Y | H39: =IFERROR(INDEX(計畫總表!$F$2:$F$27,MATCH(G39,計畫總表!$A$2:$A$27,0)),"") | I39: 完整版未收錄
A40: 41 | B40: 中小及新創企業署 | C40: 科技應用驅動中小微企業包容成長計畫 | D40: 創業資源整備服務計畫（115年度臺灣創業服務發展計畫） | E40: Y | H40: =IFERROR(INDEX(計畫總表!$F$2:$F$27,MATCH(G40,計畫總表!$A$2:$A$27,0)),"") | I40: 完整版未收錄
...

Sheet 統計
A1: 政府AI計畫統計(公式依「計畫總表」自動計算)
A2: 查證基準日(輸入) | B2: 46315 | C2: 改此日期,申請狀態與距截止天數會重新計算
A4: 類別 | B4: 項數
A5: 研發補助與投資 | B5: =COUNTIF(計畫總表!$C$2:$C$27,A5) -> 12
A6: 導入輔導與補助 | B6: =COUNTIF(計畫總表!$C$2:$C$27,A6) -> 5
A7: 工具、算力或平台 | B7: =COUNTIF(計畫總表!$C$2:$C$27,A7) -> 7
A8: AI人才培訓 | B8: =COUNTIF(計畫總表!$C$2:$C$27,A8) -> 2
A9: 合計 | B9: =SUM(B5:B8) -> 26
A11: 主辦部會 | B11: 項數 | C11: 補助上限最大值(萬元)
A12: 經濟部 | B12: =COUNTIF(計畫總表!$D$2:$D$27,A12) -> 13 | C12: =SUMPRODUCT(MAX((計畫總表!$D$2:$D$27=A12)*計畫總表!$I$2:$I$27)) -> 3000
A13: 數位發展部 | B13: =COUNTIF(計畫總表!$D$2:$D$27,A13) -> 7 | C13: =SUMPRODUCT(MAX((計畫總表!$D$2:$D$27=A13)*計畫總表!$I$2:$I$27)) -> 2000
A14: 國科會 | B14: =COUNTIF(計畫總表!$D$2:$D$27,A14) -> 2 | C14: =SUMPRODUCT(MAX((計畫總表!$D$2:$D$27=A14)*計畫總表!$I$2:$I$27)) -> 3000
A15: 農業部 | B15: =COUNTIF(計畫總表!$D$2:$D$27,A15) -> 1 | C15: =SUMPRODUCT(MAX((計畫總表!$D$2:$D$27=A15)*計畫總表!$I$2:$I$27)) -> 0
A16: 衛生福利部 | B16: =COUNTIF(計畫總表!$D$2:$D$27,A16) -> 1 | C16: =SUMPRODUCT(MAX((計畫總表!$D$2:$D$27=A16)*計畫總表!$I$2:$I$27)) -> 750
A17: 勞動部 | B17: =COUNTIF(計畫總表!$D$2:$D$27,A17) -> 2 | C17: =SUMPRODUCT(MAX((計畫總表!$D$2:$D$27=A17)*計畫總表!$I$2:$I$27)) -> 10
A18: 合計 | B18: =SUM(B12:B17) -> 26
A20: 申請狀態(截至基準日) | B20: 項數
A21: 受理中 | B21: =COUNTIF(計畫總表!$Q$2:$Q$27,A21) -> 3
A22: 已截止 | B22: =COUNTIF(計畫總表!$Q$2:$Q$27,A22) -> 8
A23: 常態開放 | B23: =COUNTIF(計畫總表!$Q$2:$Q$27,A23) -> 2
A24: 未確認 | B24: =COUNTIF(計畫總表!$Q$2:$Q$27,A24) -> 10
A25: 未確認(可能已用罄) | B25: =COUNTIF(計畫總表!$Q$2:$Q$27,A25) -> 1
A26: 未確認(計畫結束中) | B26: =COUNTIF(計畫總表!$Q$2:$Q$27,A26) -> 1
A27: 已結束 | B27: =COUNTIF(計畫總表!$Q$2:$Q$27,A27) -> 1
A28: 合計 | B28: =SUM(B21:B27) -> 26
A30: 查證結果 | B30: 項數
A31: 已核對(官方) | B31: =COUNTIF(計畫總表!$S$2:$S$27,A31) -> 4
A32: 部分核對 | B32: =COUNTIF(計畫總表!$S$2:$S$27,A32) -> 13
A33: 僅媒體或二手 | B33: =COUNTIF(計畫總表!$S$2:$S$27,A33) -> 9
A34: 合計 | B34: =SUM(B31:B33) -> 26
A36: 企業可直接申請? | B36: 項數
A37: 是 | B37: =COUNTIF(計畫總表!$M$2:$M$27,A37) -> 10
A38: 限特定對象 | B38: =COUNTIF(計畫總表!$M$2:$M$27,A38) -> 10
A39: 否 | B39: =COUNTIF(計畫總表!$M$2:$M$27,A39) -> 4
A40: 未確認 | B40: =COUNTIF(計畫總表!$M$2:$M$27,A40) -> 2
A41: 合計 | B41: =SUM(B37:B40) -> 26
A43: 115年中小企業競爭力方案 | B43: 項數
A44: 有出現在上傳清單(打勾) | B44: =COUNTIF(計畫總表!$G$2:$G$27,"✓") -> 3
A45: 未出現 | B45: =COUNTA(計畫總表!$A$2:$A$27)-B44 -> 23
A46: 合計 | B46: =SUM(B44:B45) -> 26
...

Sheet 查證紀錄
A1: 項目 | B1: 先前回答的說法 | C1: 核對後 | D1: 影響 | E1: 依據
A2: 智慧機械-產業聚落供應鏈數位串流暨AI應用 | B2: 先期顧問規劃案補助上限500萬元 | C2: 115年3月版申請須知:每案上限1,500萬元,不超過總經費50%;收件至2026-05-04,已截止 | D2: 更正金額與狀態 | E2: https://keid.nat.gov.tw/cloud/Web/UpWebload/ACE60748-3BEA-43F0-B094-9783B1E3039B.pdf(500萬為114年版)
A3: AI創新服務研發補助計畫(數發部) | B3: 列出期程至115/11/16與116/11/16,容易被當成申請期限 | C3: 申請截止為2026-07-24 16:59:59,已截止;11/16為計畫期程 | D3: 更正狀態 | E3: https://www.jfetek.com/news/6(顧問網站,未取得原公告)
A4: 第二、三類AI中心補助計畫(衛福部) | B4: 只寫補助金額與執行期 | C4: 受理至2026-09-21,已截止;對象為完成114年度計畫的醫院 | D4: 補充狀態與對象 | E4: https://www.mohw.gov.tw/cp-7283-87899-1.html
A5: AI算力平台(數發部) | B5: 對象為資訊服務業與新創 | C5: 申請資格涵蓋軟體、資訊服務、電商、第三方支付等數位經濟產業;成立未滿8年新創優先;截止2026-10-30 23:59(確認) | D5: 補充資格 | E5: https://www-api.moda.gov.tw/File/Get/adi/zh-tw/owvBgtTcGlT8cjT
A6: 雲市集工業館-AI工具庫點數補助 | B6: 受理至2026-10-30 | C6: 中小企業處官方頁確認2026-10-30 17:30;輔導資源查詢頁卻寫117年10月20日;另有部落格稱點數2026-07已用罄 | D6: 衝突未解,需向產發署確認 | E6: https://www.sme.gov.tw/caas/article-caas-3059-20513 ;https://assist.nat.gov.tw/wSite/ct?ctNode=150&mp=2&xItem=289607
A7: 產業競爭力輔導團診斷補助 | B7: 政府補助19萬+企業自付1萬 | C7: 官方PDF摘要顯示18萬+自付2萬;多數報導為19萬+1萬;兩者合計皆為20萬 | D7: 衝突未解,以申請須知為準 | E7: https://eii.nat.gov.tw/moeai-plus/uploads/downloads/01KXHVG2BBBWKXBZ991F4NEFQD.pdf
A8: A+ AI應用躍昇計畫 | B8: 補助上限每案3,000萬 | C8: 官方新聞:導入型2,000萬(SI加碼1,000萬)、擴散型2,000萬,合計最高3,000萬;114年度受理至2025-11-28;115年度徵案未查到 | D8: 補充說明,狀態標為已截止 | E8: https://www.moea.gov.tw/MNS/populace/news/News.aspx?kind=1&menu_id=40&news_id=120600
A9: 產業競爭力輔導團成效 | B9: 9,249家、93%中小企業、397項AI工具 | C9: 中央社2026-07-09報導逐項相符;另載帶動產值323億元、AI普及率38.5% | D9: 已核對 | E9: https://www.cna.com.tw/news/afe/202607090138.aspx
A10: 中企署提升中小企業智慧化經營效能計畫 | B10: 三大措施、診斷培訓導入 | C10: 官方新聞確認;申請至2026-03-10,已截止;AI導入應用輔導每案輔導總經費最高350萬 | D10: 補充金額與狀態 | E10: https://www.moea.gov.tw/MNS/populace/news/News.aspx?kind=1&menu_id=40&news_id=121811
A11: 主題式-製造業AI升級擴散與機器人 | B11: 只有計畫名稱 | C11: 產業署公告2026-05-29,受理至2026-06-30,已截止;補助上限未載 | D11: 補充狀態 | E11: https://www.ida.gov.tw/ctlr?PRO=news.rwdNewsView&id=43221
A12: IC設計攻頂補助計畫 | B12: 晶片補助,重點為AI應用 | C12: 115年度受理至2026-03-31,已截止 | D12: 補充狀態 | E12: https://service.moea.gov.tw/EE514/tw/aiip/336.html
... A16: 115年方案彙整分頁(新增) | B16: (新增) | C16: 38項完整版未收錄的方案依上傳清單補齊;截至2026-10-20:23項已截止、2項受理中(A+STEP至2026-12-31、服務業AI人才培育至2026-11-30)、3項額度用罄為止、10項為未確認、分項期限不同或非申請制(含4項委辦案);另抽查4項官網,頁面未載詳細資訊 | D16: 彙整資料以上傳清單為準,金額與期限申請前請至公告網站確認 | E16: 使用者提供的 20260820_v3.xlsx;newtrade.taiwantrade.com

Sheet 說明
A1: 說明與假設
A2: 查證基準日 | B2: 2026-10-20(Asia/Taipei);基準日在統計頁B2,可修改
A3: 資料範圍 | B3: 合併前兩則回答:經濟部(第一則)與其他中央部會(第二則),共26列
A4: 115年中小企業競爭力方案欄 | B4: 與你提供的 20260820_v3.xlsx(經濟部115年度政策資源彙整表)比對;出現者打勾。打勾由「比對結果」分頁的對應編號自動產生,要改對應請改該分頁G欄
A5: 比對方式 | B5: 以計畫實質內容判斷,不只看名稱;共41列政策資源,3項對應到完整版。上傳檔只含經濟部計畫,因此其他部會的列不會打勾
A6: 分類方式 | B6: 把原先混在一起的輔導、診斷、導入補助獨立為「導入輔導與補助」,與「研發補助與投資」分開
A7: 申請狀態 | B7: 有截止日者以公式比對基準日判斷受理中或已截止;無截止日者為手填狀態(常態開放、未確認、已結束)
A8: 查證結果 | B8: 已核對(官方)=讀取官方頁面或公告原文;部分核對=官方頁面只核對一部分,或來源為輔導顧問網站;僅媒體或二手=只有媒體、部落格、校方轉載
A9: 補助上限 | B9: 單位萬元;定義不同(每案、每人、每家、點數),不可直接加總;統計頁只取各部會最大值
A10: 無法讀取的來源 | B10: 產業署網頁(ida.gov.tw)與產業升級創新平台(eii.nat.gov.tw/tiip)禁止自動擷取,相關內容僅依搜尋摘要或其他頁面
A11: 尚未納入 | B11: 上傳清單中完整版未收錄的方案見「比對結果」分頁(對應編號空白者),其中名稱或簡述提到AI的,統計頁有計數
A12: 時效提醒 | B12: 金額與期限常調整,申請前請以各計畫官網為準
A13: 115年方案彙整分頁 | B13: 依上傳清單(經濟部115年度政策資源彙整表)建立,欄位同「計畫總表」,另加「完整版已收錄」「完整版編號」「上傳清單列號」。完整版已有者(3項)打勾且只留名稱,其餘38項依上傳清單補齊資料
... A16: 彙整分頁的上限 | B16: 金額欄寫「配合款上限」或比例而非政府款上限者,上限欄留空,原文在「上限定義」欄;多級額度者上限填最高者
